Workbook

Sheet attack-vectors-knowledge-base
A1: ID | B1: Scope | C1: Vector | D1: Category | E1: Kill_chain_phase | F1: Severity_default | G1: Description | H1: Impact | I1: Test_approach | J1: Remediation | K1: Detection_note | L1: OWASP_Top10_2025 | M1: OWASP_API_2023 | N1: WSTG | O1: ASVS_5.0 | P1: MITRE_ATTACK | Q1: CWE | R1: PayloadsAllTheThings | S1: OSCP_plus | T1: CISSP_domain | U1: Evidence | V1: CVSS_score | W1: CVSS_vector | X1: Affected_versions | Y1: Fixed_in | Z1: CISA_KEV | AA1: Exploit_public | AB1: Related_IDs | AC1: Other_mapping | AD1: References | AE1: Last_updated
A2: AV-WEB-01 | B2: Web application | C2: Broken access control / IDOR | D2: Authorization | E2: Privilege escalation | F2: High | G2: Object references without a server-side authorization check allow access to other users' data. | H2: Unauthorized access to or manipulation of someone else's records. | I2: Swap object identifiers and roles and check whether authorization is enforced server-side (see WSTG-ATHZ). | J2: Enforce authorization centrally per object and per function; use indirect references. | K2: Log and alert on access to objects outside the user's scope. | L2: A01:2025 | M2: API1:2023 | N2: WSTG-ATHZ-04 | O2: V8 | P2: T1078 | Q2: CWE-639, CWE-284 | R2: Insecure Direct Object References | S2: Web attacks | T2: D5 | AB2: AV-API-01 | AD2: https://owasp.org/www-project-web-security-testing-guide/latest/4-Web_Application_Security_Testing/05-Authorization_Testing/04-Testing_for_Insecure_Direct_Object_References | AE2: 2026-10-09
A3: AV-WEB-02 | B3: Web application | C3: Vertical privilege escalation | D3: Authorization | E3: Privilege escalation | F3: High | G3: A lower-privileged user reaches functions or data intended for higher roles. | H3: Takeover of admin functionality or sensitive actions. | I3: Access admin endpoints with a user account and check role enforcement (WSTG-ATHZ). | J3: Deny-by-default, role check on every function, no reliance on hidden UI. | K3: Alert on admin actions by non-admin accounts. | L3: A01:2025 | M3: API5:2023 | N3: WSTG-ATHZ-02, WSTG-ATHZ-03 | O3: V8 | P3: T1068, T1078 | Q3: CWE-269 | R3: Privilege Escalation | S3: Web attacks | T3: D5 | AB3: AV-API-05, CVE-2025-29927, CVE-2023-22515 | AE3: 2026-10-09
A4: AV-WEB-03 | B4: Web application | C4: SQL injection | D4: Injection | E4: Execution | F4: High | G4: Untrusted input is interpreted as SQL, making queries manipulable. | H4: Reading, modifying or deleting database contents; sometimes code execution. | I4: Test input fields for injection via anomalous behavior and error messages; confirm with a review for parameterized queries (WSTG-INPV). | J4: Parameterized queries / prepared statements; least-privilege DB accounts. | K4: WAF and DB anomaly detection for unusual query patterns. | L4: A05:2025 | N4: WSTG-INPV-05 | O4: V1, V2 | P4: T1190 | Q4: CWE-89 | R4: SQL Injection | S4: Web attacks | T4: D8 | AB4: AV-WEB-36, CVE-2023-34362, CVE-2026-9082, CVE-2026-72898 | AE4: 2026-10-09
A5: AV-WEB-04 | B5: Web application | C5: Command injection | D5: Injection | E5: Execution | F5: Critical | G5: Input reaches an OS command interpreter and allows execution of system commands. | H5: Execution of commands on the host, potentially full compromise. | I5: Identify functions that invoke OS commands and check whether input is sanitized (WSTG-INPV). | J5: Avoid shell calls; use safe APIs and strict allowlists. | K5: Monitor for unexpected child processes of web processes. | L5: A05:2025 | N5: WSTG-INPV-12 | O5: V1 | P5: T1190, T1059 | Q5: CWE-78 | R5: Command Injection | S5: Web attacks | T5: D8 | AB5: AV-HOST-02, CVE-2024-4577, CVE-2014-6271, CVE-2024-3400 | AE5: 2026-10-09
A6: AV-WEB-05 | B6: Web application | C6: Reflected XSS | D6: Injection / client-side | E6: Execution | F6: Medium | G6: Unencoded input is reflected directly in the response and executed in the browser. | H6: Script execution in the victim's context; session theft, phishing. | I6: Check whether reflected input is encoded correctly for its context (WSTG-CLNT). | J6: Output encoding per context; Content Security Policy as an additional layer. | K6: Log CSP report endpoints and anomalous URL parameters. | L6: A05:2025 | N6: WSTG-INPV-01 | O6: V1, V3 | P6: T1059.007, T1539 | Q6: CWE-79 | R6: XSS Injection | S6: Web attacks | T6: D8 | AB6: AV-WEB-41, AV-WEB-42, AV-WEB-19 | AE6: 2026-10-09
A7: AV-WEB-06 | B7: Web application | C7: Stored XSS | D7: Injection / client-side | E7: Execution | F7: High | G7: Malicious input is stored and later displayed unencoded to other users. | H7: Wide reach; script runs for every visitor of the affected page. | I7: Submit marked input and check the encoding when it is displayed elsewhere (WSTG-CLNT). | J7: Output encoding and input sanitization; CSP. | K7: Monitor content integrity and CSP violations. | L7: A05:2025 | N7: WSTG-INPV-02 | O7: V1, V3 | P7: T1059.007, T1539 | Q7: CWE-79 | R7: XSS Injection | S7: Web attacks | T7: D8 | AB7: AV-WEB-41, AV-WEB-05 | AE7: 2026-10-09
A8: AV-WEB-07 | B8: Web application | C8: Server-side request forgery (SSRF) | D8: Access control | E8: Discovery | F8: High | G8: The server is induced to access internal or unintended destinations. | H8: Access to internal services, metadata endpoints and network reconnaissance. | I8: Check whether user-controlled URLs are validated server-side against an allowlist (WSTG-INPV). | J8: Allowlist for destinations; block internal ranges and metadata IPs. | K8: Egress filtering and alerting on internal calls from app servers. | L8: A01:2025 | N8: WSTG-INPV-19 | O8: V4 | P8: T1190 | Q8: CWE-918 | R8: Server Side Request Forgery | S8: Web attacks | T8: D8 | AB8: AV-API-07, AV-CLD-05, CVE-2021-26855, CVE-2026-64849 | AE8: 2026-10-09
A9: AV-WEB-08 | B9: Web application | C9: XML external entity (XXE) | D9: Injection | E9: Execution | F9: High | G9: An XML parser processes external entities and allows file or network access. | H9: Reading local files, SSRF and denial of service. | I9: Check whether XML parsers disable external entities and DTDs (WSTG-INPV). | J9: Disable DTD/external entity processing in the parser. | K9: Alert on outbound calls from XML-processing components. | L9: A05:2025 | N9: WSTG-INPV-07 | O9: V1 | P9: T1190 | Q9: CWE-611 | R9: XXE Injection | S9: Web attacks | T9: D8 | AB9: AV-WEB-31 | AE9: 2026-10-09
A10: AV-WEB-09 | B10: Web application | C10: Insecure deserialization | D10: Integrity | E10: Execution | F10: High | G10: Untrusted serialized data is processed without an integrity check. | H10: Object injection up to and including remote code execution. | I10: Identify deserialization points and check for integrity/type checks (WSTG-INPV). | J10: Avoid native deserialization of untrusted data; use signed formats. | K10: Monitor for deserialization errors and unexpected object types. | L10: A08:2025 | N10: WSTG-INPV (no specific test) | O10: V1 | P10: T1190 | Q10: CWE-502 | R10: Insecure Deserialization | S10: Web attacks | T10: D8 | AB10: CVE-2025-53770, CVE-2025-55182, CVE-2023-46604, CVE-2019-18935, CVE-2025-59287 | AE10: 2026-10-09
A11: AV-WEB-10 | B11: Web application | C11: Unrestricted file upload | D11: File handling | E11: Execution | F11: High | G11: Uploads are insufficiently validated for type, content and storage location. | H11: Placement of executable files; possible code execution. | I11: Check server-side validation of type/content and whether storage is outside the webroot (WSTG-BUSL/INPV). | J11: Validate content, rename files, store outside the webroot, block execution. | K11: Monitor upload directories for executable files. | L11: A05:2025 | N11: WSTG-BUSL-08, WSTG-BUSL-09 | O11: V5 | P11: T1190, T1505.003 | Q11: CWE-434 | R11: Upload Insecure Files | S11: Web attacks | T11: D8 | AB11: CVE-2025-31324, CVE-2020-14008, CVE-2021-21972 | AE11: 2026-10-09
A12: AV-WEB-11 | B12: Web application | C12: Path traversal / LFI / RFI | D12: Access control | E12: Discovery | F12: High | G12: Path manipulation gives access to files outside the intended directory. | H12: Reading sensitive files; sometimes inclusion and execution. | I12: Check whether file paths are normalized and restricted server-side (WSTG-ATHZ). | J12: Canonicalize paths, use allowlists, avoid user input in paths. | K12: Alert on traversal patterns in file requests. | L12: A01:2025 | N12: WSTG-ATHZ-01 | O12: V5 | P12: T1190, T1083 | Q12: CWE-22, CWE-98 | R12: Directory Traversal / File Inclusion | S12: Web attacks | T12: D8 | AB12: CVE-2021-41773, CVE-2021-43798, CVE-2018-13379, CVE-2019-19781 | AE12: 2026-10-09
A13: AV-WEB-12 | B13: Web application | C13: Authentication weaknesses | D13: Authentication | E13: Credential access | F13: High | G13: Weak login mechanisms allow brute force, credential stuffing or bypass. | H13: Account takeover and unauthorized access. | I13: Check lockout, rate limiting, MFA and reset flows (WSTG-ATHN). | J13: Strong MFA, rate limiting, secure reset flows, credential screening. | K13: Alert on login anomalies and spikes in failed logins. | L13: A07:2025 | M13: API2:2023 | N13: WSTG-ATHN-03, WSTG-ATHN-07, WSTG-ATHN-09 | O13: V6 | P13: T1110, T1078 | Q13: CWE-307, CWE-521 | R13: Account Takeover | S13: Web attacks | T13: D5 | AB13: AV-WEB-43, AV-WEB-44, AV-WEB-45, AV-WEB-46, AV-API-02 | AE13: 2026-10-09
A14: AV-WEB-13 | B14: Web application | C14: Session management flaws | D14: Session | E14: Credential access | F14: Medium | G14: Weak session tokens, fixation or missing invalidation undermine session security. | H14: Session hijacking and persistent unauthorized access. | I14: Check token entropy, rotation at login, and logout/timeout invalidation (WSTG-SESS). | J14: Secure cookie attributes, rotation after auth, correct invalidation. | K14: Detect concurrent use of sessions from multiple locations. | L14: A07:2025 | N14: WSTG-SESS-01, WSTG-SESS-03, WSTG-SESS-06, WSTG-SESS-07 | O14: V7 | P14: T1539, T1550.004 | Q14: CWE-384, CWE-613 | R14: Session Management | S14: Web attacks | T14: D5 | AB14: AV-WEB-47, AV-WEB-53, CVE-2023-4966 | AE14: 2026-10-09
A15: AV-WEB-14 | B15: Web application | C15: JWT / token weaknesses | D15: Session / tokens | E15: Credential access | F15: High | G15: Incorrect validation of self-contained tokens (e.g. alg confusion, weak keys). | H15: Forgery of identity and privileges. | I15: Check signature validation, algorithm allowlist and claim verification (WSTG-SESS). | J15: Validate signature and alg strictly; short lifetime; strong keys. | K15: Alert on tokens with an unexpected alg or issuer. | L15: A07:2025 | N15: WSTG-SESS-10 | O15: V9 | P15: T1606 | Q15: CWE-347 | R15: JSON Web Token | S15: Web attacks | T15: D5 | AB15: AV-WEB-30, CVE-2026-5430 | AE15: 2026-10-09
A16: AV-WEB-15 | B16: Web application | C16: Cross-site request forgery (CSRF) | D16: Client-side | E16: Execution | F16: Medium | G16: An authenticated user unknowingly performs a state-changing request. | H16: Unwanted actions on behalf of the victim. | I16: Check anti-CSRF tokens and SameSite cookie policy on state-changing endpoints (WSTG-SESS). | J16: Anti-CSRF tokens, SameSite cookies, re-authentication for sensitive actions. | K16: Detect state changes without the expected token/origin. | L16: A01:2025 | N16: WSTG-SESS-05 | O16: V3 | Q16: CWE-352 | R16: CSRF Injection | S16: Web attacks | T16: D8 | AB16: AV-WEB-33, AV-WEB-47 | AE16: 2026-10-09
A17: AV-WEB-16 | B17: Web application | C17: Server-side template injection (SSTI) | D17: Injection | E17: Execution | F17: High | G17: Input is evaluated by a template engine instead of being treated as data. | H17: Template evaluation up to and including code execution. | I17: Check whether user input stays outside the template context (WSTG-INPV). | J17: Treat input as data; use logic-less templates; sandbox. | K17: Monitor template errors and unexpected evaluations. | L17: A05:2025 | N17: WSTG-INPV-18 | O17: V1 | P17: T1190 | Q17: CWE-1336 | R17: Server Side Template Injection | S17: Web attacks | T17: D8 | AB17: AV-WEB-39, CVE-2023-22527, CVE-2026-75650 | AE17: 2026-10-09
A18: AV-WEB-17 | B18: Web application | C18: Open redirect | D18: Input validation | E18: Initial access | F18: Low | G18: Unvalidated redirect parameters send users to external destinations. | H18: Phishing and bypass of origin trust. | I18: Check whether redirect targets are validated against an allowlist (WSTG-CLNT). | J18: Allowlist of redirect targets; avoid user-controlled URLs. | K18: Log redirects to external domains. | L18: A01:2025 | N18: WSTG-CLNT-04 | O18: V2 | P18: T1566.002 | Q18: CWE-601 | R18: Open Redirect | S18: Web attacks | T18: D8 | AB18: AV-WEB-30 | AE18: 2026-10-09
A19: AV-WEB-18 | B19: Web application | C19: Security misconfiguration | D19: Configuration | E19: Reconnaissance | F19: Medium | G19: Default settings, unnecessary features or exposed management interfaces. | H19: Varies, from information leakage to direct compromise. | I19: Check hardening, default credentials and exposed interfaces (WSTG-CONF). | J19: Hardening baselines, remove defaults, minimize features. | K19: Config drift detection and periodic hardening scans. | L19: A02:2025 | N19: WSTG-CONF-02, WSTG-CONF-05 | O19: V13 | P19: T1592 | Q19: CWE-16, CWE-1188 | R19: Methodology and Resources | S19: Enumeration | T19: D3 | AB19: AV-WEB-48, AV-WEB-49, AV-EXT-07 | AE19: 2026-10-09
A20: AV-WEB-19 | B20: Web application | C20: Missing security headers | D20: Configuration | E20: Reconnaissance | F20: Low | G20: Missing headers (CSP, HSTS, X-Frame-Options) weaken browser defenses. | H20: Greater likelihood of XSS, clickjacking and downgrade. | I20: Check the presence and correctness of security headers (WSTG-CONF). | J20: Set CSP, HSTS, X-Content-Type-Options and frame-ancestors. | K20: Periodic header scans in CI. | L20: A02:2025 | N20: WSTG-CONF-07, WSTG-CONF-12 | O20: V3 | Q20: CWE-693 | R20: Methodology and Resources | S20: Enumeration | T20: D3 | AB20: AV-WEB-27, AV-WEB-47 | AE20: 2026-10-09
A21: AV-WEB-20 | B21: Web application | C21: Cryptographic failures / weak TLS | D21: Cryptography | E21: Credential access | F21: Medium | G21: Weak algorithms, outdated TLS or poor key management. | H21: Exposure or manipulation of sensitive data in transit or at rest. | I21: Check TLS config, algorithm choice and key management (WSTG-CRYP). | J21: Modern TLS, strong suites, correct key management and crypto agility. | K21: Monitor for outdated protocol versions and cipher downgrades. | L21: A04:2025 | N21: WSTG-CRYP-01, WSTG-CRYP-04 | O21: V11, V12 | P21: T1557, T1040 | Q21: CWE-327 | R21: Methodology and Resources | S21: Enumeration | T21: D3 | AB21: AV-NET-18, CVE-2014-0160 | AE21: 2026-10-09
A22: AV-WEB-21 | B22: Web application | C22: Sensitive data exposure | D22: Data protection | E22: Collection | F22: Medium | G22: Sensitive data is insufficiently protected or unnecessarily exposed. | H22: Data breach and privacy violation. | I22: Check data classification, encryption and minimization in responses (WSTG-ATHZ/CONF). | J22: Classify data, encrypt at rest/in transit, minimize fields. | K22: DLP and monitoring for unusual data egress. | L22: A04:2025 | N22: WSTG-CRYP-03, WSTG-INFO-05 | O22: V14 | P22: T1005, T1213 | Q22: CWE-200 | R22: Methodology and Resources | S22: Enumeration | T22: D2 | AB22: AV-WEB-48, AV-WEB-53 | AE22: 2026-10-09
A23: AV-WEB-22 | B23: Web application | C23: Business logic flaws | D23: Business logic | E23: Execution | F23: Medium | G23: Legitimate functionality is exploited in unintended ways (e.g. workflow bypass, race conditions). | H23: Fraud, bypass of limits and integrity damage. | I23: Model the intended workflows and test deviating sequences and concurrency (WSTG-BUSL). | J23: Server-side enforcement of workflow, atomic operations, limits. | K23: Alert on impossible or overly fast workflow transitions. | L23: A06:2025 | N23: WSTG-BUSL-01, WSTG-BUSL-06 | O23: V2 | Q23: CWE-840 | R23: Methodology and Resources | S23: Web attacks | T23: D8 | AB23: AV-WEB-34, AV-API-06 | AE23: 2026-10-09
A24: AV-WEB-23 | B24: Web application | C24: Vulnerable & outdated components | D24: Supply chain | E24: Initial access | F24: High | G24: Outdated libraries or frameworks with known vulnerabilities. | H24: Exploitation of known CVEs in dependencies. | I24: Inventory dependencies and compare versions against known advisories (WSTG-CONF). | J24: SBOM, dependency scanning, timely patching. | K24: Continuous SCA and version monitoring in the pipeline. | L24: A03:2025 | N24: WSTG-INFO-02, WSTG-INFO-08 | O24: V15 | P24: T1190 | Q24: CWE-1104 | R24: Methodology and Resources | S24: Enumeration | T24: D8 | AB24: CVE-2021-44228, CVE-2022-22965, CVE-2017-5638, AV-CLD-19, AV-NET-21 | AE24: 2026-10-09
A25: AV-WEB-24 | B25: Web application | C25: Improper error handling | D25: Error handling | E25: Reconnaissance | F25: Low | G25: Verbose errors leak details or the application fails open instead of closed. | H25: Information leakage and bypass of controls on exceptions. | I25: Force error conditions and assess leakage and fail-open behavior (WSTG-ERRH). | J25: Generic error pages, fail-closed design, structured logging. | K25: Monitor for stack traces in responses. | L25: A10:2025 | N25: WSTG-ERRH-01, WSTG-ERRH-02 | O25: V16 | Q25: CWE-209 | R25: Methodology and Resources | S25: Web attacks | T25: D8 | AB25: AV-WEB-48 | AE25: 2026-10-09
A26: AV-WEB-25 | B26: Web application | C26: HTTP request smuggling / desync | D26: Injection | E26: Execution | F26: High | G26: Front-end (proxy/load balancer) and back-end interpret Content-Length/Transfer-Encoding (or HTTP/2 downgrade) differently, allowing an attacker to smuggle a second request into the connection. | H26: Bypass of front-end security controls, hijacking of other users' requests, cache poisoning and sometimes account takeover. | I26: Test CL.TE, TE.CL and H2.CL desync with timing-based probes on the front-end; confirm only with non-destructive payloads and per the RoE (WSTG-INPV-15). | J26: Use end-to-end HTTP/2 or normalize ambiguous requests on the front-end; reject requests with both CL and TE; close back-end connections after every request; patch proxy/web server. | K26: Alert on 400/timeout spikes and on requests with conflicting CL/TE headers at the edge. | L26: A06:2025 | N26: WSTG-INPV-15 | O26: V4, V13 | P26: T1190 | Q26: CWE-444 | R26: Request Smuggling | S26: Web attacks | T26: D8 | AD26: https://portswigger.net/web-security/request-smuggling | AE26: 2026-10-09
A27: AV-WEB-26 | B27: Web application | C27: CORS misconfiguration | D27: Configuration | E27: Collection | F27: Medium | G27: Access-Control-Allow-Origin reflects arbitrary or null origins (often combined with Allow-Credentials: true), allowing a malicious site to read authenticated responses. | H27: Cross-origin theft of sensitive data and CSRF-like actions on behalf of the victim. | I27: Send requests with deviating Origin headers (arbitrary, null, subdomain variants) and check ACAO/ACAC in the response (WSTG-CLNT-07). | J27: Strict allowlist of origins; never reflect the Origin header with credentials; no wildcard on authenticated endpoints. | K27: Log and review Origin headers on authenticated endpoints; periodic header scan in CI. | L27: A01:2025 | M27: API8:2023 | N27: WSTG-CLNT-07 | O27: V3 | Q27: CWE-942 | R27: CORS Misconfiguration | S27: Web attacks | T27: D8 | AD27: https://portswigger.net/web-security/cors | AE27: 2026-10-09
A28: AV-WEB-27 | B28: Web application | C28: Clickjacking / UI redressing | D28: Client-side | E28: Execution | F28: Low | G28: Pages with state-changing functionality can be loaded in an (invisible) frame on an attacker's domain due to missing frame-ancestors/X-Frame-Options. | H28: User unintentionally performs actions (e.g. changing settings, confirming transactions). | I28: Check CSP frame-ancestors and X-Frame-Options on sensitive pages and create a framing PoC (WSTG-CLNT-09). | J28: Content-Security-Policy: frame-ancestors 'none' or an allowlist; X-Frame-Options as fallback; re-authentication for sensitive actions. | K28: Header scan in CI; CSP violation reporting. | L28: A02:2025 | N28: WSTG-CLNT-09 | O28: V3 | Q28: CWE-1021 | R28: Clickjacking | S28: Web attacks | T28: D8 | AB28: AV-WEB-19 | AD28: https://cheatsheetseries.owasp.org/cheatsheets/Clickjacking_Defense_Cheat_Sheet.html | AE28: 2026-10-09
A29: AV-WEB-28 | B29: Web application | C29: Subdomain takeover (dangling DNS) | D29: Configuration | E29: Initial access | F29: Medium | G29: A CNAME/A record points to a no-longer-claimed external service (cloud storage, SaaS, CDN), allowing an attacker to claim the destination and serve content under the trusted domain. | H29: Phishing under the organization's own domain, cookie theft for parent-domain cookies, bypass of CSP/CORS trust. | I29: Enumerate subdomains and check DNS records for references to unclaimed services (fingerprints per provider) (WSTG-CONF-10). | J29: Remove orphaned DNS records during decommissioning; inventory DNS periodically; claim resources before DNS is created. | K29: Periodic DNS inventory and monitoring for CNAMEs to external services without an active resource. | L29: A02:2025 | N29: WSTG-CONF-10 | O29: V13 | P29: T1584.001 | Q29: CWE-284 | R29: Methodology and Resources - Subdomains Enumeration | S29: Enumeration | T29: D4 | AB29: AV-EXT-04 | AD29: https://github.com/EdOverflow/can-i-take-over-xyz | AE29: 2026-10-09
A30: AV-WEB-29 | B30: Web application | C30: Host header injection / password reset poisoning | D30: Injection | E30: Credential access | F30: Medium | G30: The application uses the Host or X-Forwarded-Host header to build absolute URLs (e.g. in password reset emails), allowing an attacker to inject links to their own domain. | H30: Theft of reset tokens and account takeover; cache poisoning and SSRF-like routing. | I30: Manipulate Host/X-Forwarded-Host and check whether generated links, redirects or cache keys adopt the value (WSTG-INPV-17). | J30: Use a configured canonical hostname; validate Host against an allowlist; ignore X-Forwarded-Host unless from a trusted proxy. | K30: Alert on requests with unknown Host values at the edge. | L30: A05:2025 | N30: WSTG-INPV-17 | O30: V2, V4 | P30: T1566.002 | Q30: CWE-644, CWE-20 | R30: Methodology and Resources | S30: Web attacks | T30: D8 | AB30: AV-WEB-45 | AD30: https://portswigger.net/web-security/host-header | AE30: 2026-10-09
A31: AV-WEB-30 | B31: Web application | C31: OAuth 2.0 / OIDC misconfiguration | D31: Authentication | E31: Credential access | F31: High | G31: Weak redirect_uri validation, missing state/PKCE, implicit flow or overly broad scopes enable theft of authorization codes or access tokens. | H31: Account takeover via token theft or login CSRF; access to APIs on behalf of the victim. | I31: Test redirect_uri variants (path/subdomain/open redirect), absence of state/nonce/PKCE, token leakage via Referer and scope escalation (WSTG-ATHZ-05). | J31: Exact redirect_uri matching, authorization code flow with PKCE, mandatory state/nonce, short token lifetime, scope minimization. | K31: Alert on authorization requests with a deviating redirect_uri or unusual client/scopes. | L31: A07:2025 | M31: API2:2023 | N31: WSTG-ATHZ-05 | O31: V10 | P31: T1528, T1550.001 | Q31: CWE-601, CWE-287 | R31: OAuth Misconfiguration | S31: Web attacks | T31: D5 | AB31: AV-WEB-17, AV-CLD-10 | AD31: https://portswigger.net/web-security/oauth | AE31: 2026-10-09
A32: AV-WEB-31 | B32: Web application | C32: SAML / SSO implementation flaws | D32: Authentication | E32: Credential access | F32: High | G32: Incorrect validation of SAML responses (signature wrapping, missing/weak signature check, XXE in assertions, missing audience/recipient check) allows identity forgery. | H32: Impersonation of arbitrary users including administrators at the service provider. | I32: Manipulate SAML responses (remove/replace signature, XSW, attribute modification, replay) and check whether the SP rejects the assertion. | J32: Use a maintained SAML library, validate the signature on the assertion and response, check audience/recipient/NotOnOrAfter, disable DTD processing. | K32: Alert on SAML responses with signature errors or a deviating issuer/audience. | L32: A07:2025 | N32: WSTG-ATHN-04 | O32: V6, V9 | P32: T1606.002 | Q32: CWE-347, CWE-287 | R32: SAML Injection | S32: Web attacks | T32: D5 | AB32: CVE-2022-47966 | AD32: https://cheatsheetseries.owasp.org/cheatsheets/SAML_Security_Cheat_Sheet.html | AE32: 2026-10-09
A33: AV-WEB-32 | B33: Web application | C33: GraphQL-specific weaknesses | D33: Configuration | E33: Discovery | F33: Medium | G33: Introspection in production, missing authorization per resolver, batching/aliasing without limits and deep queries enable information leakage, brute force and DoS. | H33: Exposure of schema and data, bypass of rate limiting, resource exhaustion. | I33: Check introspection, per-field authorization, query depth/complexity limits and batching abuse (WSTG-APIT-01). | J33: Introspection off in production, authorization in the resolver layer, depth/complexity/cost limits, limit batching and aliasing. | K33: Monitor for introspection queries and unusually complex/large queries. | L33: A01:2025 | M33: API4:2023, API8:2023 | N33: WSTG-APIT-01 | O33: V4 | Q33: CWE-200, CWE-770 | R33: GraphQL Injection | S33: Web attacks | T33: D8 | AB33: AV-API-04 | AD33: https://cheatsheetseries.owasp.org/cheatsheets/GraphQL_Cheat_Sheet.html | AE33: 2026-10-09
A34: AV-WEB-33 | B34: Web application | C34: WebSocket weaknesses (CSWSH, missing auth) | D34: Session | E34: Execution | F34: Medium | G34: WebSocket handshakes without Origin validation or without (re-)authentication allow cross-site WebSocket hijacking and unauthorized messages; messages are often not validated. | H34: Reading and sending messages on behalf of the victim; injection via unprotected message processing. | I34: Test the handshake with a foreign Origin and without a session cookie; fuzz message content for injection (WSTG-CLNT-10). | J34: Validate Origin, use tokens in the handshake, apply the same authorization and input validation as on HTTP endpoints, use wss://. | K34: Log handshakes with an unknown Origin; monitor message volume per session. | L34: A01:2025 | N34: WSTG-CLNT-10 | O34: V3, V4 | Q34: CWE-1385, CWE-346 | R34: Web Sockets | S34: Web attacks | T34: D8 | AB34: AV-WEB-15 | AD34: https://portswigger.net/web-security/websockets | AE34: 2026-10-09
A35: AV-WEB-34 | B35: Web application | C35: Race conditions / TOCTOU | D35: Business logic | E35: Execution | F35: Medium | G35: Concurrent requests on non-atomic operations (vouchers, balance, limits, OTP attempts, registration) allow limits to be exceeded or checks to be bypassed. | H35: Financial fraud, double payout, bypass of rate limits and one-time actions. | I35: Send parallel requests (single-packet/last-byte-sync) to limit-bound functions and compare the final state with the expected limit (WSTG-BUSL-05). | J35: Atomic database operations/locks, idempotency keys, server-side state machine, unique constraints. | K35: Alert on multiple successful transactions within milliseconds for the same entity. | L35: A06:2025 | M35: API6:2023 | N35: WSTG-BUSL-05 | O35: V2 | Q35: CWE-362, CWE-367 | R35: Race Condition | S35: Web attacks | T35: D8 | AB35: AV-WEB-22 | AD35: https://portswigger.net/web-security/race-conditions | AE35: 2026-10-09
A36: AV-WEB-35 | B36: Web application | C36: Web cache poisoning / cache deception | D36: Configuration | E36: Execution | F36: Medium | G36: Unkeyed input (headers, parameters, path normalization) influences cached responses, or sensitive personal responses are cached under a static-looking path. | H36: Spread of XSS/redirects to all visitors, or exposure of personal data via the cache. | I36: Identify cache behavior (headers, keys) and test unkeyed inputs and path confusion (/account/x.css) for cacheability. | J36: Cache only explicitly static content, normalize path/parameters consistently on CDN and origin, set Cache-Control: no-store on personal responses. | K36: Monitor cache hit ratios and anomalous cache keys; alert on cached responses with Set-Cookie. | L36: A06:2025 | N36: WSTG-CONF-13 | O36: V3, V13 | Q36: CWE-444, CWE-524 | R36: Web Cache Deception | S36: Web attacks | T36: D8 | AB36: AV-WEB-25 | AD36: https://portswigger.net/web-security/web-cache-poisoning | AE36: 2026-10-09
A37: AV-WEB-36 | B37: Web application | C37: NoSQL injection | D37: Injection | E37: Execution | F37: High | G37: Input is included unfiltered in NoSQL queries (MongoDB operators such as $ne/$regex/$where, JSON objects). | H37: Authentication bypass, reading of collections, sometimes server-side JavaScript execution. | I37: Inject operator objects and JSON type changes into parameters/bodies and observe behavioral deviations (WSTG-INPV-05). | J37: Strict schema/type validation, forbid operator keys in input, use parameterized query builders, disable server-side JS. | K37: Alert on query operators in request bodies and on anomalous query patterns in the database. | L37: A05:2025 | N37: WSTG-INPV-05 | O37: V1 | P37: T1190 | Q37: CWE-943 | R37: NoSQL Injection | S37: Web attacks | T37: D8 | AB37: AV-WEB-03 | AD37: https://cheatsheetseries.owasp.org/cheatsheets/Injection_Prevention_Cheat_Sheet.html | AE37: 2026-10-09
A38: AV-WEB-37 | B38: Web application | C38: LDAP / XPath injection | D38: Injection | E38: Execution | F38: High | G38: Input is included without escaping in LDAP filters or XPath expressions (e.g. login forms against AD or XML datastores). | H38: Authentication bypass, enumeration of directory objects and reading of XML data. | I38: Inject filter metacharacters (*, (, ), |, &) and XPath booleans and check for deviating results (WSTG-INPV-06, WSTG-INPV-09). | J38: Escape per context with a library, use allowlists for input, bind with least-privilege service accounts. | K38: Alert on LDAP queries with unusual filters from the application. | L38: A05:2025 | N38: WSTG-INPV-06, WSTG-INPV-09 | O38: V1 | P38: T1190 | Q38: CWE-90, CWE-643 | R38: LDAP Injection | S38: Web attacks | T38: D8 | AD38: https://cheatsheetseries.owasp.org/cheatsheets/LDAP_Injection_Prevention_Cheat_Sheet.html | AE38: 2026-10-09
A39: AV-WEB-38 | B39: Web application | C39: CRLF / HTTP header / e-mail header injection | D39: Injection | E39: Execution | F39: Medium | G39: Line breaks in input are not filtered when building HTTP headers, log lines or email headers (SMTP). | H39: Response splitting, cookie injection, log pollution, spam/phishing via the organization's own mail server. | I39: Inject %0d%0a into parameters that end up in headers, redirects or mail fields and check the output (WSTG-INPV-15, WSTG-INPV-10). | J39: Strip or encode CR/LF, use framework APIs for headers and mail, validate email fields strictly. | K39: Monitor for unexpected extra headers or anomalous mail volumes from the application. | L39: A05:2025 | N39: WSTG-INPV-15, WSTG-INPV-10 | O39: V1 | Q39: CWE-113, CWE-93 | R39: CRLF Injection | S39: Web attacks | T39: D8 | AD39: https://owasp.org/www-community/vulnerabilities/CRLF_Injection | AE39: 2026-10-09
A40: AV-WEB-39 | B40: Web application | C40: Code injection (eval) / expression language injection | D40: Injection | E40: Execution | F40: Critical | G40: Input is evaluated by an interpreter or expression language (eval(), OGNL, SpEL, EL, Jinja expressions outside templates). | H40: Direct code execution on the server; full compromise. | I40: Inject arithmetic and language-specific expressions into suspicious parameters and check whether they are evaluated (WSTG-INPV-11). | J40: Avoid dynamic evaluation of input; use safe parsers; sandbox and least privilege. | K40: Monitor for unexpected child processes and for expression syntax in requests. | L40: A05:2025 | N40: WSTG-INPV-11 | O40: V1 | P40: T1190, T1059 | Q40: CWE-94, CWE-917 | R40: Methodology and Resources | S40: Web attacks | T40: D8 | AB40: AV-WEB-16, CVE-2022-26134, CVE-2017-5638 | AD40: https://owasp.org/www-community/attacks/Code_Injection | AE40: 2026-10-09
...

Sheet Legend
A1: Attack-vectors knowledge base - Legend (version 0.10.0, 2026-10-09)
A3: Column | B3: Meaning | C3: Values / convention
A4: ID | B4: Unique key of the row. | C4: AV-<SCOPE>-<nn> for attack vectors (WEB, API, NET, EXT, AD, CLD, MOB, WIFI, SE, PHY, HOST, AI); CVE-yyyy-nnnnn for known vulnerabilities.
A5: Scope | B5: Test scope in which the vector/vulnerability is typically encountered. | C5: Web application | API | Internal network | External network | Active Directory | Cloud | Mobile | Wireless | Social engineering | Physical | Endpoint | AI / LLM
A6: Vector | B6: Short English name of the attack technique or vulnerability (report title). | C6: Free text; CVE rows: "<Product> - <type> (<nickname>)".
A7: Category | B7: Class of the finding. | C7: E.g. Authorization, Injection, Configuration, Credential access, Known vulnerability (all CVE rows).
A8: Kill_chain_phase | B8: Phase (MITRE ATT&CK tactic) in which the technique is typically used. | C8: Reconnaissance | Initial access | Execution | Persistence | Privilege escalation | Defense evasion | Credential access | Discovery | Lateral movement | Collection | Command and control | Impact
A9: Severity_default | B9: Indicative default severity for reporting; adjust to context and evidence. | C9: Info | Low | Medium | High | Critical. For CVE rows based on practical pentest impact; the formal CVSS score is in CVSS_score.
A10: Description / Impact / Test_approach / Remediation / Detection_note | B10: Report text (EN; translated from the Dutch original, which by convention was written without diacritics). | C10: Test_approach describes a non-destructive approach within the rules of engagement (RoE).
A11: OWASP_Top10_2025 | B11: Mapping to OWASP Top 10 2025. | C11: A01 Broken Access Control, A02 Security Misconfiguration, A03 Software Supply Chain Failures, A04 Cryptographic Failures, A05 Injection, A06 Insecure Design, A07 Authentication Failures, A08 Software or Data Integrity Failures, A09 Security Logging & Alerting Failures, A10 Mishandling of Exceptional Conditions. CVE rows receive A03:2025 (vulnerable component) plus the underlying class.
A12: OWASP_API_2023 | B12: Mapping to OWASP API Security Top 10 2023. | C12: API1 through API10.
A13: WSTG | B13: OWASP Web Security Testing Guide test ID (v4.2 / latest). | C13: E.g. WSTG-ATHZ-04 (IDOR), WSTG-INPV-05 (SQLi), WSTG-SESS-10 (JWT), WSTG-APIT-01 (GraphQL). The category prefix remains filterable.
A14: ASVS_5.0 | B14: Chapter of OWASP ASVS 5.0. | C14: V1 Encoding/Sanitization, V2 Validation/Business Logic, V3 Web Frontend, V4 API/Web Service, V5 File Handling, V6 Authentication, V7 Session, V8 Authorization, V9 Self-contained Tokens, V10 OAuth/OIDC, V11 Cryptography, V12 Secure Communication, V13 Configuration, V14 Data Protection, V15 Secure Coding/Architecture, V16 Logging/Error Handling, V17 WebRTC.
... A28: Last_updated | B28: Date of last review/change of the row. | C28: ISO date (yyyy-mm-dd).
A30: Sources and reference dates
A31: CVE records: CVEProject/cvelistV5 (CNA descriptions, CVSS, CISA-ADP incl. KEV date), as of 2026-10-04.
A32: CISA Known Exploited Vulnerabilities Catalog (via the ADP container in the CVE records), as of 2026-10-04.
A33: OWASP Top 10 2025, OWASP API Security Top 10 2023, OWASP WSTG v4.2/latest, OWASP ASVS 5.0, OWASP Mobile Top 10 2024 / MASVS 2.x, OWASP Top 10 for LLM Applications 2025.
A34: MITRE ATT&CK Enterprise (v17/v18) and MITRE ATLAS.
A35: Vendor advisories (MSRC, Fortinet PSIRT, Citrix/NetScaler, Ivanti, Palo Alto Networks, Cisco PSIRT, Broadcom/VMware, Atlassian, Oracle CPU, SAP, Adobe, GitLab, JetBrains, JFrog and others).
A36: Severity_default, Test_approach, Remediation and Detection_note are editorial choices for reporting; CVSS/KEV/versions are taken from the sources.

Sheet Changelog
A1: Version | B1: Date | C1: Component | D1: Change
A2: 0.10.0 | B2: 2026-10-09 | C2: Structure | D2: 10 columns added after Evidence: CVSS_score, CVSS_vector, Affected_versions, Fixed_in, CISA_KEV, Exploit_public, Related_IDs, Other_mapping, References, Last_updated. Existing 21 columns, order and header names unchanged.
A3: 0.10.0 | B3: 2026-10-09 | C3: Structure | D3: Header row bold with fill, frozen first row/column (ID), autofilter across the entire table; Legend, Changelog and Overview tabs added.
A4: 0.10.0 | B4: 2026-10-09 | C4: Attack vectors | D4: 108 new AV rows (total 195): Web +29, API +2, Internal network +14, External network (new) +7, Active Directory +14, Cloud +11, Mobile +4, Wireless +4, Social engineering +5, Physical +4, Endpoint (new) +7, AI / LLM (new) +7.
A5: 0.10.0 | B5: 2026-10-09 | C5: Attack vectors | D5: New scopes: External network (AV-EXT), Endpoint (AV-HOST) and AI / LLM (AV-AI) with mapping to OWASP LLM Top 10 2025 and MITRE ATLAS.
A6: 0.10.0 | B6: 2026-10-09 | C6: Existing rows | D6: WSTG column refined from category (e.g. WSTG-ATHZ) to specific test IDs (e.g. WSTG-ATHZ-04); reflected/stored XSS moved from WSTG-CLNT to WSTG-INPV-01/02 in line with WSTG.
A7: 0.10.0 | B7: 2026-10-09 | C7: Existing rows | D7: MITRE ATT&CK supplemented where a defensible mapping exists (including SQLi/SSRF/XXE/SSTI -> T1190, file upload -> T1505.003, session -> T1539, JWT -> T1606, TLS -> T1557/T1040); AV-AD-08 (ACL abuse) corrected to T1098, T1484.001.
A8: 0.10.0 | B8: 2026-10-09 | C8: Existing rows | D8: AV-AD-09 extended from ESC1-ESC8 to ESC1-ESC16 (incl. ESC9/10 certificate mapping, ESC15 EKUwu, ESC16) with Certipy reference; AV-NET-02 extended with ADIDNS wildcard abuse; AV-WEB-11 renamed to "Path traversal / LFI / RFI"; AV-AD-01 remediation supplemented with RC4 disabling; AV-CLD-03 extended with snapshots/SAS tokens; AV-WEB-18 CWE-1188 added.
A9: 0.10.0 | B9: 2026-10-09 | C9: Existing rows | D9: Related_IDs and Other_mapping (MASVS / OWASP Mobile Top 10 2024, CIS, Certipy) filled in; OWASP_API_2023 supplemented for AV-WEB-01/02/12 (IDOR, privesc, auth).
A10: 0.10.0 | B10: 2026-10-09 | C10: CVE rows | D10: 154 CVE rows (was 1). Row CVE-2020-14008 translated into Dutch, supplemented (CVSS 7.2, build 14730, KEV status, WSTG/CWE/MITRE) and category typo "Known Vulnerabillity" corrected to "Known vulnerability".
A11: 0.10.0 | B11: 2026-10-09 | C11: CVE rows | D11: Selection criteria: exploited in the wild (CISA KEV) and/or structurally encountered in pentests of Dutch organizations; per scope: Active Directory (11), Internal network (25), External network (47), Web application (38), Endpoint (10), Social engineering (5), Cloud (7), AI / LLM (11). 137 of the 154 CVE rows are in the CISA KEV catalog. Coverage through KEV additions of 2026-10-04 (including CVE-2026-104286 FortiMail, CVE-2026-88771 NetScaler, CVE-2026-63030 WordPress, CVE-2026-33824 Windows IKEEXT).
A12: 0.10.0 | B12: 2026-10-09 | C12: CVE rows | D12: CVSS score/vector, KEV date and references automatically taken from the official CVE records (cvelistV5, CNA and CISA-ADP); temporal metrics removed from vectors. Exceptions documented in Other_mapping (CVE-2020-1472 NVD 10.0 instead of CNA 5.5; CVE-2020-14008 NVD 7.2; CVE-2013-4786 CVSSv2 only).
... A14: 0.10.0 | B14: 2026-10-09 | C14: Points of attention | D14: When reporting, check the current NVD score and the vendor advisory; version numbers are summarized. Severity_default is indicative. All rows with Last_updated 2026-10-09 were reviewed in this release.
A15: 0.9.1 | C15: Baseline | D15: Original knowledge base: 87 attack vectors (9 scopes) and 1 CVE row.
A16: 0.10.0-EN | B16: 2026-10-11 | C16: Translation | D16: Full English translation of all tabs (attack-vectors-knowledge-base, Legend, Changelog, Overview) from the Dutch 0.10.0 original. IDs, mappings, versions, CVSS, KEV dates, references and formulas unchanged; CISA_KEV values "Ja/Nee" are now "Yes/No" (Overview formulas adjusted accordingly); tabs "Legenda" and "Overzicht" renamed to "Legend" and "Overview".

Sheet Overview
A1: Overview of counts per scope and Severity_default (formulas on the attack-vectors-knowledge-base tab)
A3: Scope | B3: Info | C3: Low | D3: Medium | E3: High | F3: Critical | G3: Total | H3: of which CVE rows | I3: of which in KEV
A4: Web application | B4: =COUNTIFS('attack-vectors-knowledge-base'!$B:$B,$A4,'attack-vectors-knowledge-base'!$F:$F,B$3) -> 0 | C4: =COUNTIFS('attack-vectors-knowledge-base'!$B:$B,$A4,'attack-vectors-knowledge-base'!$F:$F,C$3) -> 8 | D4: =COUNTIFS('attack-vectors-knowledge-base'!$B:$B,$A4,'attack-vectors-knowledge-base'!$F:$F,D$3) -> 24 | E4: =COUNTIFS('attack-vectors-knowledge-base'!$B:$B,$A4,'attack-vectors-knowledge-base'!$F:$F,E$3) -> 22 | F4: =COUNTIFS('attack-vectors-knowledge-base'!$B:$B,$A4,'attack-vectors-knowledge-base'!$F:$F,F$3) -> 37 | G4: =SUM(B4:F4) -> 91 | H4: =COUNTIFS('attack-vectors-knowledge-base'!$B:$B,$A4,'attack-vectors-knowledge-base'!$D:$D,"Known vulnerability") -> 38 | I4: =COUNTIFS('attack-vectors-knowledge-base'!$B:$B,$A4,'attack-vectors-knowledge-base'!$Z:$Z,"Yes*") -> 36
A5: API | B5: =COUNTIFS('attack-vectors-knowledge-base'!$B:$B,$A5,'attack-vectors-knowledge-base'!$F:$F,B$3) -> 0 | C5: =COUNTIFS('attack-vectors-knowledge-base'!$B:$B,$A5,'attack-vectors-knowledge-base'!$F:$F,C$3) -> 0 | D5: =COUNTIFS('attack-vectors-knowledge-base'!$B:$B,$A5,'attack-vectors-knowledge-base'!$F:$F,D$3) -> 7 | E5: =COUNTIFS('attack-vectors-knowledge-base'!$B:$B,$A5,'attack-vectors-knowledge-base'!$F:$F,E$3) -> 5 | F5: =COUNTIFS('attack-vectors-knowledge-base'!$B:$B,$A5,'attack-vectors-knowledge-base'!$F:$F,F$3) -> 0 | G5: =SUM(B5:F5) -> 12 | H5: =COUNTIFS('attack-vectors-knowledge-base'!$B:$B,$A5,'attack-vectors-knowledge-base'!$D:$D,"Known vulnerability") -> 0 | I5: =COUNTIFS('attack-vectors-knowledge-base'!$B:$B,$A5,'attack-vectors-knowledge-base'!$Z:$Z,"Yes*") -> 0
A6: Internal network | B6: =COUNTIFS('attack-vectors-knowledge-base'!$B:$B,$A6,'attack-vectors-knowledge-base'!$F:$F,B$3) -> 1 | C6: =COUNTIFS('attack-vectors-knowledge-base'!$B:$B,$A6,'attack-vectors-knowledge-base'!$F:$F,C$3) -> 0 | D6: =COUNTIFS('attack-vectors-knowledge-base'!$B:$B,$A6,'attack-vectors-knowledge-base'!$F:$F,D$3) -> 9 | E6: =COUNTIFS('attack-vectors-knowledge-base'!$B:$B,$A6,'attack-vectors-knowledge-base'!$F:$F,E$3) -> 20 | F6: =COUNTIFS('attack-vectors-knowledge-base'!$B:$B,$A6,'attack-vectors-knowledge-base'!$F:$F,F$3) -> 18 | G6: =SUM(B6:F6) -> 48 | H6: =COUNTIFS('attack-vectors-knowledge-base'!$B:$B,$A6,'attack-vectors-knowledge-base'!$D:$D,"Known vulnerability") -> 25 | I6: =COUNTIFS('attack-vectors-knowledge-base'!$B:$B,$A6,'attack-vectors-knowledge-base'!$Z:$Z,"Yes*") -> 22
A7: External network | B7: =COUNTIFS('attack-vectors-knowledge-base'!$B:$B,$A7,'attack-vectors-knowledge-base'!$F:$F,B$3) -> 1 | C7: =COUNTIFS('attack-vectors-knowledge-base'!$B:$B,$A7,'attack-vectors-knowledge-base'!$F:$F,C$3) -> 1 | D7: =COUNTIFS('attack-vectors-knowledge-base'!$B:$B,$A7,'attack-vectors-knowledge-base'!$F:$F,D$3) -> 2 | E7: =COUNTIFS('attack-vectors-knowledge-base'!$B:$B,$A7,'attack-vectors-knowledge-base'!$F:$F,E$3) -> 6 | F7: =COUNTIFS('attack-vectors-knowledge-base'!$B:$B,$A7,'attack-vectors-knowledge-base'!$F:$F,F$3) -> 44 | G7: =SUM(B7:F7) -> 54 | H7: =COUNTIFS('attack-vectors-knowledge-base'!$B:$B,$A7,'attack-vectors-knowledge-base'!$D:$D,"Known vulnerability") -> 47 | I7: =COUNTIFS('attack-vectors-knowledge-base'!$B:$B,$A7,'attack-vectors-knowledge-base'!$Z:$Z,"Yes*") -> 47
A8: Active Directory | B8: =COUNTIFS('attack-vectors-knowledge-base'!$B:$B,$A8,'attack-vectors-knowledge-base'!$F:$F,B$3) -> 1 | C8: =COUNTIFS('attack-vectors-knowledge-base'!$B:$B,$A8,'attack-vectors-knowledge-base'!$F:$F,C$3) -> 0 | D8: =COUNTIFS('attack-vectors-knowledge-base'!$B:$B,$A8,'attack-vectors-knowledge-base'!$F:$F,D$3) -> 6 | E8: =COUNTIFS('attack-vectors-knowledge-base'!$B:$B,$A8,'attack-vectors-knowledge-base'!$F:$F,E$3) -> 27 | F8: =COUNTIFS('attack-vectors-knowledge-base'!$B:$B,$A8,'attack-vectors-knowledge-base'!$F:$F,F$3) -> 4 | G8: =SUM(B8:F8) -> 38 | H8: =COUNTIFS('attack-vectors-knowledge-base'!$B:$B,$A8,'attack-vectors-knowledge-base'!$D:$D,"Known vulnerability") -> 11 | I8: =COUNTIFS('attack-vectors-knowledge-base'!$B:$B,$A8,'attack-vectors-knowledge-base'!$Z:$Z,"Yes*") -> 8
A9: Cloud | B9: =COUNTIFS('attack-vectors-knowledge-base'!$B:$B,$A9,'attack-vectors-knowledge-base'!$F:$F,B$3) -> 1 | C9: =COUNTIFS('attack-vectors-knowledge-base'!$B:$B,$A9,'attack-vectors-knowledge-base'!$F:$F,C$3) -> 0 | D9: =COUNTIFS('attack-vectors-knowledge-base'!$B:$B,$A9,'attack-vectors-knowledge-base'!$F:$F,D$3) -> 3 | E9: =COUNTIFS('attack-vectors-knowledge-base'!$B:$B,$A9,'attack-vectors-knowledge-base'!$F:$F,E$3) -> 18 | F9: =COUNTIFS('attack-vectors-knowledge-base'!$B:$B,$A9,'attack-vectors-knowledge-base'!$F:$F,F$3) -> 4 | G9: =SUM(B9:F9) -> 26 | H9: =COUNTIFS('attack-vectors-knowledge-base'!$B:$B,$A9,'attack-vectors-knowledge-base'!$D:$D,"Known vulnerability") -> 7 | I9: =COUNTIFS('attack-vectors-knowledge-base'!$B:$B,$A9,'attack-vectors-knowledge-base'!$Z:$Z,"Yes*") -> 3
A10: Mobile | B10: =COUNTIFS('attack-vectors-knowledge-base'!$B:$B,$A10,'attack-vectors-knowledge-base'!$F:$F,B$3) -> 0 | C10: =COUNTIFS('attack-vectors-knowledge-base'!$B:$B,$A10,'attack-vectors-knowledge-base'!$F:$F,C$3) -> 1 | D10: =COUNTIFS('attack-vectors-knowledge-base'!$B:$B,$A10,'attack-vectors-knowledge-base'!$F:$F,D$3) -> 8 | E10: =COUNTIFS('attack-vectors-knowledge-base'!$B:$B,$A10,'attack-vectors-knowledge-base'!$F:$F,E$3) -> 2 | F10: =COUNTIFS('attack-vectors-knowledge-base'!$B:$B,$A10,'attack-vectors-knowledge-base'!$F:$F,F$3) -> 0 | G10: =SUM(B10:F10) -> 11 | H10: =COUNTIFS('attack-vectors-knowledge-base'!$B:$B,$A10,'attack-vectors-knowledge-base'!$D:$D,"Known vulnerability") -> 0 | I10: =COUNTIFS('attack-vectors-knowledge-base'!$B:$B,$A10,'attack-vectors-knowledge-base'!$Z:$Z,"Yes*") -> 0
A11: Wireless | B11: =COUNTIFS('attack-vectors-knowledge-base'!$B:$B,$A11,'attack-vectors-knowledge-base'!$F:$F,B$3) -> 0 | C11: =COUNTIFS('attack-vectors-knowledge-base'!$B:$B,$A11,'attack-vectors-knowledge-base'!$F:$F,C$3) -> 1 | D11: =COUNTIFS('attack-vectors-knowledge-base'!$B:$B,$A11,'attack-vectors-knowledge-base'!$F:$F,D$3) -> 2 | E11: =COUNTIFS('attack-vectors-knowledge-base'!$B:$B,$A11,'attack-vectors-knowledge-base'!$F:$F,E$3) -> 6 | F11: =COUNTIFS('attack-vectors-knowledge-base'!$B:$B,$A11,'attack-vectors-knowledge-base'!$F:$F,F$3) -> 0 | G11: =SUM(B11:F11) -> 9 | H11: =COUNTIFS('attack-vectors-knowledge-base'!$B:$B,$A11,'attack-vectors-knowledge-base'!$D:$D,"Known vulnerability") -> 0 | I11: =COUNTIFS('attack-vectors-knowledge-base'!$B:$B,$A11,'attack-vectors-knowledge-base'!$Z:$Z,"Yes*") -> 0
A12: Social engineering | B12: =COUNTIFS('attack-vectors-knowledge-base'!$B:$B,$A12,'attack-vectors-knowledge-base'!$F:$F,B$3) -> 0 | C12: =COUNTIFS('attack-vectors-knowledge-base'!$B:$B,$A12,'attack-vectors-knowledge-base'!$F:$F,C$3) -> 0 | D12: =COUNTIFS('attack-vectors-knowledge-base'!$B:$B,$A12,'attack-vectors-knowledge-base'!$F:$F,D$3) -> 4 | E12: =COUNTIFS('attack-vectors-knowledge-base'!$B:$B,$A12,'attack-vectors-knowledge-base'!$F:$F,E$3) -> 11 | F12: =COUNTIFS('attack-vectors-knowledge-base'!$B:$B,$A12,'attack-vectors-knowledge-base'!$F:$F,F$3) -> 1 | G12: =SUM(B12:F12) -> 16 | H12: =COUNTIFS('attack-vectors-knowledge-base'!$B:$B,$A12,'attack-vectors-knowledge-base'!$D:$D,"Known vulnerability") -> 5 | I12: =COUNTIFS('attack-vectors-knowledge-base'!$B:$B,$A12,'attack-vectors-knowledge-base'!$Z:$Z,"Yes*") -> 5
A13: Physical | B13: =COUNTIFS('attack-vectors-knowledge-base'!$B:$B,$A13,'attack-vectors-knowledge-base'!$F:$F,B$3) -> 0 | C13: =COUNTIFS('attack-vectors-knowledge-base'!$B:$B,$A13,'attack-vectors-knowledge-base'!$F:$F,C$3) -> 1 | D13: =COUNTIFS('attack-vectors-knowledge-base'!$B:$B,$A13,'attack-vectors-knowledge-base'!$F:$F,D$3) -> 7 | E13: =COUNTIFS('attack-vectors-knowledge-base'!$B:$B,$A13,'attack-vectors-knowledge-base'!$F:$F,E$3) -> 1 | F13: =COUNTIFS('attack-vectors-knowledge-base'!$B:$B,$A13,'attack-vectors-knowledge-base'!$F:$F,F$3) -> 0 | G13: =SUM(B13:F13) -> 9 | H13: =COUNTIFS('attack-vectors-knowledge-base'!$B:$B,$A13,'attack-vectors-knowledge-base'!$D:$D,"Known vulnerability") -> 0 | I13: =COUNTIFS('attack-vectors-knowledge-base'!$B:$B,$A13,'attack-vectors-knowledge-base'!$Z:$Z,"Yes*") -> 0
A14: Endpoint | B14: =COUNTIFS('attack-vectors-knowledge-base'!$B:$B,$A14,'attack-vectors-knowledge-base'!$F:$F,B$3) -> 0 | C14: =COUNTIFS('attack-vectors-knowledge-base'!$B:$B,$A14,'attack-vectors-knowledge-base'!$F:$F,C$3) -> 0 | D14: =COUNTIFS('attack-vectors-knowledge-base'!$B:$B,$A14,'attack-vectors-knowledge-base'!$F:$F,D$3) -> 0 | E14: =COUNTIFS('attack-vectors-knowledge-base'!$B:$B,$A14,'attack-vectors-knowledge-base'!$F:$F,E$3) -> 16 | F14: =COUNTIFS('attack-vectors-knowledge-base'!$B:$B,$A14,'attack-vectors-knowledge-base'!$F:$F,F$3) -> 1 | G14: =SUM(B14:F14) -> 17 | H14: =COUNTIFS('attack-vectors-knowledge-base'!$B:$B,$A14,'attack-vectors-knowledge-base'!$D:$D,"Known vulnerability") -> 10 | I14: =COUNTIFS('attack-vectors-knowledge-base'!$B:$B,$A14,'attack-vectors-knowledge-base'!$Z:$Z,"Yes*") -> 10
A15: AI / LLM | B15: =COUNTIFS('attack-vectors-knowledge-base'!$B:$B,$A15,'attack-vectors-knowledge-base'!$F:$F,B$3) -> 0 | C15: =COUNTIFS('attack-vectors-knowledge-base'!$B:$B,$A15,'attack-vectors-knowledge-base'!$F:$F,C$3) -> 0 | D15: =COUNTIFS('attack-vectors-knowledge-base'!$B:$B,$A15,'attack-vectors-knowledge-base'!$F:$F,D$3) -> 3 | E15: =COUNTIFS('attack-vectors-knowledge-base'!$B:$B,$A15,'attack-vectors-knowledge-base'!$F:$F,E$3) -> 6 | F15: =COUNTIFS('attack-vectors-knowledge-base'!$B:$B,$A15,'attack-vectors-knowledge-base'!$F:$F,F$3) -> 9 | G15: =SUM(B15:F15) -> 18 | H15: =COUNTIFS('attack-vectors-knowledge-base'!$B:$B,$A15,'attack-vectors-knowledge-base'!$D:$D,"Known vulnerability") -> 11 | I15: =COUNTIFS('attack-vectors-knowledge-base'!$B:$B,$A15,'attack-vectors-knowledge-base'!$Z:$Z,"Yes*") -> 6
A16: Total | B16: =SUM(B4:B15) -> 4 | C16: =SUM(C4:C15) -> 12 | D16: =SUM(D4:D15) -> 75 | E16: =SUM(E4:E15) -> 140 | F16: =SUM(F4:F15) -> 118 | G16: =SUM(G4:G15) -> 349 | H16: =SUM(H4:H15) -> 154 | I16: =SUM(I4:I15) -> 137
A18: Check: number of rows with ID in main table | B18: =COUNTA('attack-vectors-knowledge-base'!$A:$A)-1 -> 349
A19: Check: number of CVE rows (ID starts with CVE-) | B19: =SUMPRODUCT(--(LEFT('attack-vectors-knowledge-base'!$A$2:$A$2000,4)="CVE-")) -> 154
A20: Check: number of rows in KEV | B20: =SUMPRODUCT(--(LEFT('attack-vectors-knowledge-base'!$Z$2:$Z$2000,3)="Yes")) -> 137
