Workbook

Sheet attack-vectors-knowledge-base
A1: ID | B1: Scope | C1: Vector | D1: Category | E1: Kill_chain_phase | F1: Severity_default | G1: Description | H1: Impact | I1: Test_approach | J1: Remediation | K1: Detection_note | L1: OWASP_Top10_2025 | M1: OWASP_API_2023 | N1: WSTG | O1: ASVS_5.0 | P1: MITRE_ATTACK | Q1: CWE | R1: PayloadsAllTheThings | S1: OSCP_plus | T1: CISSP_domain | U1: Evidence | V1: CVSS_score | W1: CVSS_vector | X1: Affected_versions | Y1: Fixed_in | Z1: CISA_KEV | AA1: Exploit_public | AB1: Related_IDs | AC1: Other_mapping | AD1: References | AE1: Last_updated
A2: AV-WEB-01 | B2: Web application | C2: Broken access control / IDOR | D2: Authorization | E2: Privilege escalation | F2: High | G2: Object-referenties zonder server-side autorisatiecheck laten toegang tot data van andere gebruikers toe. | H2: Ongeautoriseerde toegang tot of manipulatie van andermans records. | I2: Wissel object-identifiers en rollen om en controleer of autorisatie server-side wordt afgedwongen (zie WSTG-ATHZ). | J2: Dwing autorisatie centraal af per object en per functie; gebruik indirecte referenties. | K2: Log en alarmeer op toegang tot objecten buiten het bereik van de gebruiker. | L2: A01:2025 | M2: API1:2023 | N2: WSTG-ATHZ-04 | O2: V8 | P2: T1078 | Q2: CWE-639, CWE-284 | R2: Insecure Direct Object References | S2: Web attacks | T2: D5 | AB2: AV-API-01 | AD2: https://owasp.org/www-project-web-security-testing-guide/latest/4-Web_Application_Security_Testing/05-Authorization_Testing/04-Testing_for_Insecure_Direct_Object_References | AE2: 2026-10-09
A3: AV-WEB-02 | B3: Web application | C3: Vertical privilege escalation | D3: Authorization | E3: Privilege escalation | F3: High | G3: Een lager geprivilegieerde gebruiker bereikt functies of data die voor hogere rollen bedoeld zijn. | H3: Overname van admin-functionaliteit of gevoelige acties. | I3: Benader admin-endpoints met een gebruikersaccount en controleer rol-enforcement (WSTG-ATHZ). | J3: Deny-by-default, rolcontrole op elke functie, geen vertrouwen op verborgen UI. | K3: Alarmeer op admin-acties door niet-admin-accounts. | L3: A01:2025 | M3: API5:2023 | N3: WSTG-ATHZ-02, WSTG-ATHZ-03 | O3: V8 | P3: T1068, T1078 | Q3: CWE-269 | R3: Privilege Escalation | S3: Web attacks | T3: D5 | AB3: AV-API-05, CVE-2025-29927, CVE-2023-22515 | AE3: 2026-10-09
A4: AV-WEB-03 | B4: Web application | C4: SQL injection | D4: Injection | E4: Execution | F4: High | G4: Onvertrouwde invoer wordt als SQL geinterpreteerd, waardoor queries manipuleerbaar zijn. | H4: Uitlezen, wijzigen of verwijderen van database-inhoud; soms code-uitvoering. | I4: Toets invoervelden op injectie via afwijkend gedrag en foutmeldingen; bevestig met review op parameterized queries (WSTG-INPV). | J4: Parameterized queries / prepared statements; least-privilege DB-accounts. | K4: WAF- en DB-anomaliedetectie op ongebruikelijke querypatronen. | L4: A05:2025 | N4: WSTG-INPV-05 | O4: V1, V2 | P4: T1190 | Q4: CWE-89 | R4: SQL Injection | S4: Web attacks | T4: D8 | AB4: AV-WEB-36, CVE-2023-34362, CVE-2026-9082, CVE-2026-72898 | AE4: 2026-10-09
A5: AV-WEB-04 | B5: Web application | C5: Command injection | D5: Injection | E5: Execution | F5: Critical | G5: Invoer bereikt een OS-command-interpreter en laat uitvoering van systeemcommando's toe. | H5: Uitvoering van commando's op de host, potentieel volledige compromittering. | I5: Identificeer functies die OS-commando's aanroepen en controleer of invoer wordt afgeschermd (WSTG-INPV). | J5: Vermijd shell-aanroepen; gebruik veilige API's en strikte allowlists. | K5: Monitor op onverwachte child-processen van webprocessen. | L5: A05:2025 | N5: WSTG-INPV-12 | O5: V1 | P5: T1190, T1059 | Q5: CWE-78 | R5: Command Injection | S5: Web attacks | T5: D8 | AB5: AV-HOST-02, CVE-2024-4577, CVE-2014-6271, CVE-2024-3400 | AE5: 2026-10-09
A6: AV-WEB-05 | B6: Web application | C6: Reflected XSS | D6: Injection / client-side | E6: Execution | F6: Medium | G6: Onge-encodeerde invoer wordt direct in de respons weerspiegeld en in de browser uitgevoerd. | H6: Uitvoering van script in de context van het slachtoffer; sessiediefstal, phishing. | I6: Controleer of gereflecteerde invoer context-correct wordt ge-encodeerd (WSTG-CLNT). | J6: Output-encoding per context; Content Security Policy als extra laag. | K6: CSP-report-endpoints en afwijkende URL-parameters loggen. | L6: A05:2025 | N6: WSTG-INPV-01 | O6: V1, V3 | P6: T1059.007, T1539 | Q6: CWE-79 | R6: XSS Injection | S6: Web attacks | T6: D8 | AB6: AV-WEB-41, AV-WEB-42, AV-WEB-19 | AE6: 2026-10-09
A7: AV-WEB-06 | B7: Web application | C7: Stored XSS | D7: Injection / client-side | E7: Execution | F7: High | G7: Kwaadaardige invoer wordt opgeslagen en later ongeencodeerd aan andere gebruikers getoond. | H7: Breed bereik; script draait bij elke bezoeker van de getroffen pagina. | I7: Plaats gemarkeerde invoer en controleer encoding bij weergave elders (WSTG-CLNT). | J7: Output-encoding en input-sanitisatie; CSP. | K7: Content-integriteit en CSP-violations monitoren. | L7: A05:2025 | N7: WSTG-INPV-02 | O7: V1, V3 | P7: T1059.007, T1539 | Q7: CWE-79 | R7: XSS Injection | S7: Web attacks | T7: D8 | AB7: AV-WEB-41, AV-WEB-05 | AE7: 2026-10-09
A8: AV-WEB-07 | B8: Web application | C8: Server-side request forgery (SSRF) | D8: Access control | E8: Discovery | F8: High | G8: De server wordt aangezet tot het benaderen van interne of onbedoelde bestemmingen. | H8: Toegang tot interne services, metadata-endpoints en netwerkverkenning. | I8: Controleer of gebruikersgestuurde URL's server-side worden gevalideerd tegen een allowlist (WSTG-INPV). | J8: Allowlist voor bestemmingen; blokkeer interne ranges en metadata-IP's. | K8: Egress-filtering en alarmering op interne calls vanuit app-servers. | L8: A01:2025 | N8: WSTG-INPV-19 | O8: V4 | P8: T1190 | Q8: CWE-918 | R8: Server Side Request Forgery | S8: Web attacks | T8: D8 | AB8: AV-API-07, AV-CLD-05, CVE-2021-26855, CVE-2026-64849 | AE8: 2026-10-09
A9: AV-WEB-08 | B9: Web application | C9: XML external entity (XXE) | D9: Injection | E9: Execution | F9: High | G9: Een XML-parser verwerkt externe entiteiten en laat bestands- of netwerktoegang toe. | H9: Uitlezen van lokale bestanden, SSRF en denial-of-service. | I9: Controleer of XML-parsers externe entiteiten en DTD's uitschakelen (WSTG-INPV). | J9: Schakel DTD/externe-entiteitverwerking uit in de parser. | K9: Alarmeer op uitgaande calls vanuit XML-verwerkende componenten. | L9: A05:2025 | N9: WSTG-INPV-07 | O9: V1 | P9: T1190 | Q9: CWE-611 | R9: XXE Injection | S9: Web attacks | T9: D8 | AB9: AV-WEB-31 | AE9: 2026-10-09
A10: AV-WEB-09 | B10: Web application | C10: Insecure deserialization | D10: Integrity | E10: Execution | F10: High | G10: Onvertrouwde geserialiseerde data wordt verwerkt zonder integriteitscontrole. | H10: Objectinjectie tot en met remote code execution. | I10: Identificeer deserialisatiepunten en controleer op integriteits-/typecontrole (WSTG-INPV). | J10: Vermijd native deserialisatie van onvertrouwde data; gebruik signed formaten. | K10: Monitor op deserialisatiefouten en onverwachte objecttypes. | L10: A08:2025 | N10: WSTG-INPV (geen specifieke test) | O10: V1 | P10: T1190 | Q10: CWE-502 | R10: Insecure Deserialization | S10: Web attacks | T10: D8 | AB10: CVE-2025-53770, CVE-2025-55182, CVE-2023-46604, CVE-2019-18935, CVE-2025-59287 | AE10: 2026-10-09
A11: AV-WEB-10 | B11: Web application | C11: Unrestricted file upload | D11: File handling | E11: Execution | F11: High | G11: Uploads worden onvoldoende gevalideerd op type, inhoud en opslaglocatie. | H11: Plaatsing van uitvoerbare bestanden; mogelijk code-uitvoering. | I11: Controleer server-side validatie van type/inhoud en of de opslag buiten webroot ligt (WSTG-BUSL/INPV). | J11: Valideer inhoud, hernoem bestanden, sla buiten webroot op, blokkeer uitvoering. | K11: Monitor uploadmappen op uitvoerbare bestanden. | L11: A05:2025 | N11: WSTG-BUSL-08, WSTG-BUSL-09 | O11: V5 | P11: T1190, T1505.003 | Q11: CWE-434 | R11: Upload Insecure Files | S11: Web attacks | T11: D8 | AB11: CVE-2025-31324, CVE-2020-14008, CVE-2021-21972 | AE11: 2026-10-09
A12: AV-WEB-11 | B12: Web application | C12: Path traversal / LFI / RFI | D12: Access control | E12: Discovery | F12: High | G12: Padmanipulatie geeft toegang tot bestanden buiten de bedoelde directory. | H12: Uitlezen van gevoelige bestanden; soms inclusie en uitvoering. | I12: Controleer of bestandspaden server-side worden genormaliseerd en beperkt (WSTG-ATHZ). | J12: Canonicaliseer paden, gebruik allowlists, mijd gebruikersinvoer in paden. | K12: Alarmeer op traversal-patronen in bestandsverzoeken. | L12: A01:2025 | N12: WSTG-ATHZ-01 | O12: V5 | P12: T1190, T1083 | Q12: CWE-22, CWE-98 | R12: Directory Traversal / File Inclusion | S12: Web attacks | T12: D8 | AB12: CVE-2021-41773, CVE-2021-43798, CVE-2018-13379, CVE-2019-19781 | AE12: 2026-10-09
A13: AV-WEB-12 | B13: Web application | C13: Authentication weaknesses | D13: Authentication | E13: Credential access | F13: High | G13: Zwakke inlogmechanismen laten brute force, credential stuffing of omzeiling toe. | H13: Accountovername en ongeautoriseerde toegang. | I13: Controleer lockout, rate-limiting, MFA en resetflows (WSTG-ATHN). | J13: Sterke MFA, rate-limiting, veilige resetflows, credential-screening. | K13: Alarmeer op login-anomalieen en spikes in mislukte logins. | L13: A07:2025 | M13: API2:2023 | N13: WSTG-ATHN-03, WSTG-ATHN-07, WSTG-ATHN-09 | O13: V6 | P13: T1110, T1078 | Q13: CWE-307, CWE-521 | R13: Account Takeover | S13: Web attacks | T13: D5 | AB13: AV-WEB-43, AV-WEB-44, AV-WEB-45, AV-WEB-46, AV-API-02 | AE13: 2026-10-09
A14: AV-WEB-13 | B14: Web application | C14: Session management flaws | D14: Session | E14: Credential access | F14: Medium | G14: Zwakke sessietokens, fixation of ontbrekende invalidatie ondermijnen sessieveiligheid. | H14: Sessiekaping en persistente ongeautoriseerde toegang. | I14: Controleer tokenentropie, rotatie bij login, en logout-/timeout-invalidatie (WSTG-SESS). | J14: Veilige cookie-attributen, rotatie na auth, correcte invalidatie. | K14: Detecteer gelijktijdig gebruik van sessies vanaf meerdere locaties. | L14: A07:2025 | N14: WSTG-SESS-01, WSTG-SESS-03, WSTG-SESS-06, WSTG-SESS-07 | O14: V7 | P14: T1539, T1550.004 | Q14: CWE-384, CWE-613 | R14: Session Management | S14: Web attacks | T14: D5 | AB14: AV-WEB-47, AV-WEB-53, CVE-2023-4966 | AE14: 2026-10-09
A15: AV-WEB-14 | B15: Web application | C15: JWT / token weaknesses | D15: Session / tokens | E15: Credential access | F15: High | G15: Onjuiste validatie van self-contained tokens (bv. alg-verwarring, zwakke sleutels). | H15: Vervalsing van identiteit en rechten. | I15: Controleer handtekeningvalidatie, algorithm-allowlist en claimverificatie (WSTG-SESS). | J15: Valideer handtekening en alg strikt; korte levensduur; sterke sleutels. | K15: Alarmeer op tokens met onverwachte alg of issuer. | L15: A07:2025 | N15: WSTG-SESS-10 | O15: V9 | P15: T1606 | Q15: CWE-347 | R15: JSON Web Token | S15: Web attacks | T15: D5 | AB15: AV-WEB-30, CVE-2026-5430 | AE15: 2026-10-09
A16: AV-WEB-15 | B16: Web application | C16: Cross-site request forgery (CSRF) | D16: Client-side | E16: Execution | F16: Medium | G16: Een geauthenticeerde gebruiker voert onbewust een statuswijzigend verzoek uit. | H16: Ongewenste acties namens het slachtoffer. | I16: Controleer anti-CSRF-tokens en SameSite-cookiebeleid op statuswijzigende endpoints (WSTG-SESS). | J16: Anti-CSRF-tokens, SameSite-cookies, herauthenticatie voor gevoelige acties. | K16: Detecteer statuswijzigingen zonder verwachte token/oorsprong. | L16: A01:2025 | N16: WSTG-SESS-05 | O16: V3 | Q16: CWE-352 | R16: CSRF Injection | S16: Web attacks | T16: D8 | AB16: AV-WEB-33, AV-WEB-47 | AE16: 2026-10-09
A17: AV-WEB-16 | B17: Web application | C17: Server-side template injection (SSTI) | D17: Injection | E17: Execution | F17: High | G17: Invoer wordt door een template-engine geevalueerd in plaats van als data behandeld. | H17: Template-evaluatie tot en met code-uitvoering. | I17: Controleer of gebruikersinvoer buiten de template-context blijft (WSTG-INPV). | J17: Behandel invoer als data; gebruik logic-less templates; sandbox. | K17: Monitor template-fouten en onverwachte evaluaties. | L17: A05:2025 | N17: WSTG-INPV-18 | O17: V1 | P17: T1190 | Q17: CWE-1336 | R17: Server Side Template Injection | S17: Web attacks | T17: D8 | AB17: AV-WEB-39, CVE-2023-22527, CVE-2026-75650 | AE17: 2026-10-09
A18: AV-WEB-17 | B18: Web application | C18: Open redirect | D18: Input validation | E18: Initial access | F18: Low | G18: Ongevalideerde redirect-parameters sturen gebruikers naar externe bestemmingen. | H18: Phishing en omzeiling van oorsprongvertrouwen. | I18: Controleer of redirect-doelen tegen een allowlist worden gevalideerd (WSTG-CLNT). | J18: Allowlist van redirect-doelen; vermijd gebruikersgestuurde URL's. | K18: Log redirects naar externe domeinen. | L18: A01:2025 | N18: WSTG-CLNT-04 | O18: V2 | P18: T1566.002 | Q18: CWE-601 | R18: Open Redirect | S18: Web attacks | T18: D8 | AB18: AV-WEB-30 | AE18: 2026-10-09
A19: AV-WEB-18 | B19: Web application | C19: Security misconfiguration | D19: Configuration | E19: Reconnaissance | F19: Medium | G19: Default-instellingen, onnodige features of blootgestelde beheerinterfaces. | H19: Uiteenlopend, van informatielekkage tot directe compromittering. | I19: Controleer hardening, default-credentials en blootgestelde interfaces (WSTG-CONF). | J19: Hardening-baselines, verwijder defaults, minimaliseer features. | K19: Config-drift-detectie en periodieke hardening-scans. | L19: A02:2025 | N19: WSTG-CONF-02, WSTG-CONF-05 | O19: V13 | P19: T1592 | Q19: CWE-16, CWE-1188 | R19: Methodology and Resources | S19: Enumeration | T19: D3 | AB19: AV-WEB-48, AV-WEB-49, AV-EXT-07 | AE19: 2026-10-09
A20: AV-WEB-19 | B20: Web application | C20: Missing security headers | D20: Configuration | E20: Reconnaissance | F20: Low | G20: Ontbrekende headers (CSP, HSTS, X-Frame-Options) verzwakken browserverdediging. | H20: Grotere kans op XSS, clickjacking en downgrade. | I20: Controleer aanwezigheid en correctheid van beveiligingsheaders (WSTG-CONF). | J20: Stel CSP, HSTS, X-Content-Type-Options en frame-ancestors in. | K20: Periodieke header-scans in CI. | L20: A02:2025 | N20: WSTG-CONF-07, WSTG-CONF-12 | O20: V3 | Q20: CWE-693 | R20: Methodology and Resources | S20: Enumeration | T20: D3 | AB20: AV-WEB-27, AV-WEB-47 | AE20: 2026-10-09
A21: AV-WEB-20 | B21: Web application | C21: Cryptographic failures / weak TLS | D21: Cryptography | E21: Credential access | F21: Medium | G21: Zwakke algoritmes, verouderde TLS of slecht sleutelbeheer. | H21: Blootstelling of manipulatie van gevoelige data in transit of at rest. | I21: Controleer TLS-config, algoritmekeuze en sleutelbeheer (WSTG-CRYP). | J21: Moderne TLS, sterke suites, correct sleutelbeheer en crypto-agility. | K21: Monitor op verouderde protocolversies en cipher-downgrades. | L21: A04:2025 | N21: WSTG-CRYP-01, WSTG-CRYP-04 | O21: V11, V12 | P21: T1557, T1040 | Q21: CWE-327 | R21: Methodology and Resources | S21: Enumeration | T21: D3 | AB21: AV-NET-18, CVE-2014-0160 | AE21: 2026-10-09
A22: AV-WEB-21 | B22: Web application | C22: Sensitive data exposure | D22: Data protection | E22: Collection | F22: Medium | G22: Gevoelige gegevens worden onvoldoende beschermd of onnodig blootgesteld. | H22: Datalek en privacyschending. | I22: Controleer dataclassificatie, versleuteling en minimalisatie in responses (WSTG-ATHZ/CONF). | J22: Classificeer data, versleutel at rest/in transit, minimaliseer velden. | K22: DLP en monitoring op ongebruikelijke data-egress. | L22: A04:2025 | N22: WSTG-CRYP-03, WSTG-INFO-05 | O22: V14 | P22: T1005, T1213 | Q22: CWE-200 | R22: Methodology and Resources | S22: Enumeration | T22: D2 | AB22: AV-WEB-48, AV-WEB-53 | AE22: 2026-10-09
A23: AV-WEB-22 | B23: Web application | C23: Business logic flaws | D23: Business logic | E23: Execution | F23: Medium | G23: Legitieme functionaliteit wordt op onbedoelde wijze misbruikt (bv. workflow-bypass, race conditions). | H23: Fraude, omzeiling van limieten en integriteitsschade. | I23: Modelleer bedoelde workflows en toets afwijkende volgordes en gelijktijdigheid (WSTG-BUSL). | J23: Server-side afdwinging van workflow, atomaire operaties, limieten. | K23: Alarmeer op onmogelijke of te snelle workflow-transities. | L23: A06:2025 | N23: WSTG-BUSL-01, WSTG-BUSL-06 | O23: V2 | Q23: CWE-840 | R23: Methodology and Resources | S23: Web attacks | T23: D8 | AB23: AV-WEB-34, AV-API-06 | AE23: 2026-10-09
A24: AV-WEB-23 | B24: Web application | C24: Vulnerable & outdated components | D24: Supply chain | E24: Initial access | F24: High | G24: Verouderde libraries of frameworks met bekende kwetsbaarheden. | H24: Exploitatie van bekende CVE's in afhankelijkheden. | I24: Inventariseer afhankelijkheden en vergelijk versies met bekende adviezen (WSTG-CONF). | J24: SBOM, dependency-scanning, tijdig patchen. | K24: Continu SCA en versiemonitoring in de pipeline. | L24: A03:2025 | N24: WSTG-INFO-02, WSTG-INFO-08 | O24: V15 | P24: T1190 | Q24: CWE-1104 | R24: Methodology and Resources | S24: Enumeration | T24: D8 | AB24: CVE-2021-44228, CVE-2022-22965, CVE-2017-5638, AV-CLD-19, AV-NET-21 | AE24: 2026-10-09
A25: AV-WEB-24 | B25: Web application | C25: Improper error handling | D25: Error handling | E25: Reconnaissance | F25: Low | G25: Verbose fouten lekken details of de applicatie faalt open in plaats van dicht. | H25: Informatielekkage en omzeiling van controles bij uitzonderingen. | I25: Forceer foutcondities en beoordeel lekkage en fail-open-gedrag (WSTG-ERRH). | J25: Generieke foutpagina's, fail-closed-ontwerp, gestructureerde logging. | K25: Monitor op stacktraces in responses. | L25: A10:2025 | N25: WSTG-ERRH-01, WSTG-ERRH-02 | O25: V16 | Q25: CWE-209 | R25: Methodology and Resources | S25: Web attacks | T25: D8 | AB25: AV-WEB-48 | AE25: 2026-10-09
A26: AV-WEB-25 | B26: Web application | C26: HTTP request smuggling / desync | D26: Injection | E26: Execution | F26: High | G26: Front-end (proxy/load balancer) en back-end interpreteren Content-Length/Transfer-Encoding (of HTTP/2-downgrade) verschillend, waardoor een aanvaller een tweede verzoek in de verbinding kan smokkelen. | H26: Omzeiling van front-end security controls, kaping van verzoeken van andere gebruikers, cache poisoning en soms accountovername. | I26: Toets CL.TE-, TE.CL- en H2.CL-desync met timing-based probes op de front-end; bevestig alleen met niet-destructieve payloads en per RoE (WSTG-INPV-15). | J26: Gebruik end-to-end HTTP/2 of normaliseer ambigue verzoeken op de front-end; weiger verzoeken met zowel CL als TE; sluit back-endverbindingen na elke request; patch proxy/webserver. | K26: Alarmeer op 400/timeout-pieken en op verzoeken met conflicterende CL/TE-headers op de edge. | L26: A06:2025 | N26: WSTG-INPV-15 | O26: V4, V13 | P26: T1190 | Q26: CWE-444 | R26: Request Smuggling | S26: Web attacks | T26: D8 | AD26: https://portswigger.net/web-security/request-smuggling | AE26: 2026-10-09
A27: AV-WEB-26 | B27: Web application | C27: CORS misconfiguration | D27: Configuration | E27: Collection | F27: Medium | G27: Access-Control-Allow-Origin reflecteert willekeurige of null-origins (vaak gecombineerd met Allow-Credentials: true), waardoor een kwaadaardige site geauthenticeerde responses kan uitlezen. | H27: Cross-origin diefstal van gevoelige data en CSRF-achtige acties namens het slachtoffer. | I27: Stuur verzoeken met afwijkende Origin-headers (willekeurig, null, subdomein-varianten) en controleer ACAO/ACAC in de respons (WSTG-CLNT-07). | J27: Strikte allowlist van origins; nooit reflectie van de Origin-header met credentials; geen wildcard op geauthenticeerde endpoints. | K27: Log en review Origin-headers op geauthenticeerde endpoints; periodieke header-scan in CI. | L27: A01:2025 | M27: API8:2023 | N27: WSTG-CLNT-07 | O27: V3 | Q27: CWE-942 | R27: CORS Misconfiguration | S27: Web attacks | T27: D8 | AD27: https://portswigger.net/web-security/cors | AE27: 2026-10-09
A28: AV-WEB-27 | B28: Web application | C28: Clickjacking / UI redressing | D28: Client-side | E28: Execution | F28: Low | G28: Pagina's met statuswijzigende functionaliteit kunnen in een (onzichtbaar) frame van een aanvallersdomein worden geladen door ontbrekende frame-ancestors/X-Frame-Options. | H28: Gebruiker voert onbedoeld acties uit (bv. instellingen wijzigen, transacties bevestigen). | I28: Controleer CSP frame-ancestors en X-Frame-Options op gevoelige pagina's en maak een framing-PoC (WSTG-CLNT-09). | J28: Content-Security-Policy: frame-ancestors 'none' of een allowlist; X-Frame-Options als fallback; herauthenticatie voor gevoelige acties. | K28: Header-scan in CI; CSP-violation-rapportage. | L28: A02:2025 | N28: WSTG-CLNT-09 | O28: V3 | Q28: CWE-1021 | R28: Clickjacking | S28: Web attacks | T28: D8 | AB28: AV-WEB-19 | AD28: https://cheatsheetseries.owasp.org/cheatsheets/Clickjacking_Defense_Cheat_Sheet.html | AE28: 2026-10-09
A29: AV-WEB-28 | B29: Web application | C29: Subdomain takeover (dangling DNS) | D29: Configuration | E29: Initial access | F29: Medium | G29: Een CNAME/A-record verwijst naar een niet-meer-geclaimde externe dienst (cloud storage, SaaS, CDN), waardoor een aanvaller de bestemming kan claimen en content onder het vertrouwde domein kan serveren. | H29: Phishing onder het eigen domein, cookie-diefstal voor parent-domain cookies, omzeiling van CSP/CORS-vertrouwen. | I29: Enumereer subdomeinen en controleer DNS-records op verwijzingen naar niet-geclaimde diensten (fingerprints per provider) (WSTG-CONF-10). | J29: Verwijder verweesde DNS-records bij decommissioning; inventariseer DNS periodiek; claim resources voordat DNS wordt aangemaakt. | K29: Periodieke DNS-inventaris en monitoring op CNAME's naar externe diensten zonder actieve resource. | L29: A02:2025 | N29: WSTG-CONF-10 | O29: V13 | P29: T1584.001 | Q29: CWE-284 | R29: Methodology and Resources - Subdomains Enumeration | S29: Enumeration | T29: D4 | AB29: AV-EXT-04 | AD29: https://github.com/EdOverflow/can-i-take-over-xyz | AE29: 2026-10-09
A30: AV-WEB-29 | B30: Web application | C30: Host header injection / password reset poisoning | D30: Injection | E30: Credential access | F30: Medium | G30: De applicatie gebruikt de Host- of X-Forwarded-Host-header om absolute URL's te bouwen (bv. in wachtwoordresetmails), waardoor een aanvaller links naar een eigen domein kan injecteren. | H30: Diefstal van reset-tokens en accountovername; cache poisoning en SSRF-achtige routing. | I30: Manipuleer Host/X-Forwarded-Host en controleer of gegenereerde links, redirects of cache-keys de waarde overnemen (WSTG-INPV-17). | J30: Gebruik een geconfigureerde canonieke hostname; valideer Host tegen een allowlist; negeer X-Forwarded-Host tenzij van een vertrouwde proxy. | K30: Alarmeer op verzoeken met onbekende Host-waarden op de edge. | L30: A05:2025 | N30: WSTG-INPV-17 | O30: V2, V4 | P30: T1566.002 | Q30: CWE-644, CWE-20 | R30: Methodology and Resources | S30: Web attacks | T30: D8 | AB30: AV-WEB-45 | AD30: https://portswigger.net/web-security/host-header | AE30: 2026-10-09
A31: AV-WEB-30 | B31: Web application | C31: OAuth 2.0 / OIDC misconfiguration | D31: Authentication | E31: Credential access | F31: High | G31: Zwakke redirect_uri-validatie, ontbrekende state/PKCE, implicit flow of te ruime scopes maken diefstal van authorization codes of access tokens mogelijk. | H31: Accountovername via tokendiefstal of login-CSRF; toegang tot API's namens het slachtoffer. | I31: Toets redirect_uri-varianten (pad/subdomein/open redirect), ontbreken van state/nonce/PKCE, token-leakage via Referer en scope-escalatie (WSTG-ATHZ-05). | J31: Exacte redirect_uri-matching, authorization code flow met PKCE, state/nonce verplicht, korte tokenlevensduur, scope-minimalisatie. | K31: Alarmeer op authorization-verzoeken met afwijkende redirect_uri of ongebruikelijke client/scopes. | L31: A07:2025 | M31: API2:2023 | N31: WSTG-ATHZ-05 | O31: V10 | P31: T1528, T1550.001 | Q31: CWE-601, CWE-287 | R31: OAuth Misconfiguration | S31: Web attacks | T31: D5 | AB31: AV-WEB-17, AV-CLD-10 | AD31: https://portswigger.net/web-security/oauth | AE31: 2026-10-09
A32: AV-WEB-31 | B32: Web application | C32: SAML / SSO implementation flaws | D32: Authentication | E32: Credential access | F32: High | G32: Onjuiste validatie van SAML-responses (signature wrapping, ontbrekende/zwakke signature-check, XXE in assertions, ontbrekende audience/recipient-check) laat identiteitsvervalsing toe. | H32: Impersonatie van willekeurige gebruikers inclusief beheerders bij de service provider. | I32: Manipuleer SAML-responses (verwijder/vervang signature, XSW, attribuutwijziging, replay) en controleer of de SP de assertion afwijst. | J32: Gebruik een onderhouden SAML-library, valideer signature op de assertion en response, controleer audience/recipient/NotOnOrAfter, schakel DTD-verwerking uit. | K32: Alarmeer op SAML-responses met signature-fouten of afwijkende issuer/audience. | L32: A07:2025 | N32: WSTG-ATHN-04 | O32: V6, V9 | P32: T1606.002 | Q32: CWE-347, CWE-287 | R32: SAML Injection | S32: Web attacks | T32: D5 | AB32: CVE-2022-47966 | AD32: https://cheatsheetseries.owasp.org/cheatsheets/SAML_Security_Cheat_Sheet.html | AE32: 2026-10-09
A33: AV-WEB-32 | B33: Web application | C33: GraphQL-specific weaknesses | D33: Configuration | E33: Discovery | F33: Medium | G33: Introspection in productie, ontbrekende autorisatie per resolver, batching/aliasing zonder limieten en diepe queries maken informatielekkage, brute force en DoS mogelijk. | H33: Blootstelling van schema en data, omzeiling van rate limiting, resource-uitputting. | I33: Controleer introspection, per-field autorisatie, query depth/complexity-limieten en batching-misbruik (WSTG-APIT-01). | J33: Introspection uit in productie, autorisatie in de resolver-laag, depth/complexity/cost-limieten, limiteer batching en aliasing. | K33: Monitor op introspection-queries en ongebruikelijk complexe/grote queries. | L33: A01:2025 | M33: API4:2023, API8:2023 | N33: WSTG-APIT-01 | O33: V4 | Q33: CWE-200, CWE-770 | R33: GraphQL Injection | S33: Web attacks | T33: D8 | AB33: AV-API-04 | AD33: https://cheatsheetseries.owasp.org/cheatsheets/GraphQL_Cheat_Sheet.html | AE33: 2026-10-09
A34: AV-WEB-33 | B34: Web application | C34: WebSocket weaknesses (CSWSH, missing auth) | D34: Session | E34: Execution | F34: Medium | G34: WebSocket-handshakes zonder Origin-validatie of zonder (her)authenticatie laten cross-site WebSocket hijacking en ongeautoriseerde berichten toe; berichten worden vaak niet gevalideerd. | H34: Lezen en versturen van berichten namens het slachtoffer; injectie via onbeschermde berichtverwerking. | I34: Test de handshake met een vreemde Origin en zonder sessiecookie; fuzz berichtinhoud op injectie (WSTG-CLNT-10). | J34: Valideer Origin, gebruik tokens in de handshake, pas dezelfde autorisatie en inputvalidatie toe als op HTTP-endpoints, gebruik wss://. | K34: Log handshakes met onbekende Origin; monitor berichtvolume per sessie. | L34: A01:2025 | N34: WSTG-CLNT-10 | O34: V3, V4 | Q34: CWE-1385, CWE-346 | R34: Web Sockets | S34: Web attacks | T34: D8 | AB34: AV-WEB-15 | AD34: https://portswigger.net/web-security/websockets | AE34: 2026-10-09
A35: AV-WEB-34 | B35: Web application | C35: Race conditions / TOCTOU | D35: Business logic | E35: Execution | F35: Medium | G35: Gelijktijdige verzoeken op niet-atomaire operaties (vouchers, saldo, limieten, OTP-pogingen, registratie) laten limieten overschrijden of controles omzeilen. | H35: Financiele fraude, dubbele uitbetaling, omzeiling van rate limits en eenmalige acties. | I35: Verstuur parallelle verzoeken (single-packet/last-byte-sync) op limit-gebonden functies en vergelijk de eindtoestand met de verwachte limiet (WSTG-BUSL-05). | J35: Atomaire database-operaties/locks, idempotency keys, server-side state-machine, unieke constraints. | K35: Alarmeer op meerdere geslaagde transacties binnen milliseconden voor dezelfde entiteit. | L35: A06:2025 | M35: API6:2023 | N35: WSTG-BUSL-05 | O35: V2 | Q35: CWE-362, CWE-367 | R35: Race Condition | S35: Web attacks | T35: D8 | AB35: AV-WEB-22 | AD35: https://portswigger.net/web-security/race-conditions | AE35: 2026-10-09
A36: AV-WEB-35 | B36: Web application | C36: Web cache poisoning / cache deception | D36: Configuration | E36: Execution | F36: Medium | G36: Unkeyed input (headers, parameters, path-normalisatie) beinvloedt gecachte responses, of gevoelige persoonlijke responses worden onder een statisch ogend pad gecached. | H36: Verspreiding van XSS/redirects naar alle bezoekers, of blootstelling van persoonlijke data via de cache. | I36: Identificeer cache-gedrag (headers, keys) en toets unkeyed inputs en path-confusion (/account/x.css) op cachebaarheid. | J36: Cache alleen expliciet statische content, normaliseer pad/parameters consistent op CDN en origin, zet Cache-Control: no-store op persoonlijke responses. | K36: Monitor cache-hit-ratio's en afwijkende cache-keys; alarmeer op gecachte responses met Set-Cookie. | L36: A06:2025 | N36: WSTG-CONF-13 | O36: V3, V13 | Q36: CWE-444, CWE-524 | R36: Web Cache Deception | S36: Web attacks | T36: D8 | AB36: AV-WEB-25 | AD36: https://portswigger.net/web-security/web-cache-poisoning | AE36: 2026-10-09
A37: AV-WEB-36 | B37: Web application | C37: NoSQL injection | D37: Injection | E37: Execution | F37: High | G37: Invoer wordt ongefilterd in NoSQL-queries (MongoDB-operators zoals $ne/$regex/$where, JSON-objecten) opgenomen. | H37: Authenticatie-omzeiling, uitlezen van collecties, soms server-side JavaScript-uitvoering. | I37: Injecteer operator-objecten en JSON-typeverandering in parameters/bodies en observeer gedragsafwijkingen (WSTG-INPV-05). | J37: Strikte schema-/typevalidatie, verbied operator-keys in invoer, gebruik parameterized query-builders, schakel server-side JS uit. | K37: Alarmeer op query-operators in request-bodies en op afwijkende query-patronen in de database. | L37: A05:2025 | N37: WSTG-INPV-05 | O37: V1 | P37: T1190 | Q37: CWE-943 | R37: NoSQL Injection | S37: Web attacks | T37: D8 | AB37: AV-WEB-03 | AD37: https://cheatsheetseries.owasp.org/cheatsheets/Injection_Prevention_Cheat_Sheet.html | AE37: 2026-10-09
A38: AV-WEB-37 | B38: Web application | C38: LDAP / XPath injection | D38: Injection | E38: Execution | F38: High | G38: Invoer wordt zonder escaping in LDAP-filters of XPath-expressies opgenomen (bv. loginformulieren tegen AD of XML-datastores). | H38: Authenticatie-omzeiling, enumeratie van directory-objecten en uitlezen van XML-data. | I38: Injecteer filter-metatekens (*, (, ), |, &) en XPath-booleans en controleer op afwijkende resultaten (WSTG-INPV-06, WSTG-INPV-09). | J38: Escape per context met een library, gebruik allowlists voor invoer, bind met least-privilege service-accounts. | K38: Alarmeer op LDAP-queries met ongebruikelijke filters vanuit de applicatie. | L38: A05:2025 | N38: WSTG-INPV-06, WSTG-INPV-09 | O38: V1 | P38: T1190 | Q38: CWE-90, CWE-643 | R38: LDAP Injection | S38: Web attacks | T38: D8 | AD38: https://cheatsheetseries.owasp.org/cheatsheets/LDAP_Injection_Prevention_Cheat_Sheet.html | AE38: 2026-10-09
A39: AV-WEB-38 | B39: Web application | C39: CRLF / HTTP header / e-mail header injection | D39: Injection | E39: Execution | F39: Medium | G39: Regeleinden in invoer worden niet gefilterd bij het opbouwen van HTTP-headers, logregels of e-mailheaders (SMTP). | H39: Response splitting, cookie-injectie, log-vervuiling, spam/phishing via de eigen mailserver. | I39: Injecteer %0d%0a in parameters die in headers, redirects of mailvelden belanden en controleer de uitvoer (WSTG-INPV-15, WSTG-INPV-10). | J39: Strip of encodeer CR/LF, gebruik framework-API's voor headers en mail, valideer e-mailvelden strikt. | K39: Monitor op onverwachte extra headers of afwijkende mailvolumes vanaf de applicatie. | L39: A05:2025 | N39: WSTG-INPV-15, WSTG-INPV-10 | O39: V1 | Q39: CWE-113, CWE-93 | R39: CRLF Injection | S39: Web attacks | T39: D8 | AD39: https://owasp.org/www-community/vulnerabilities/CRLF_Injection | AE39: 2026-10-09
A40: AV-WEB-39 | B40: Web application | C40: Code injection (eval) / expression language injection | D40: Injection | E40: Execution | F40: Critical | G40: Invoer wordt door een interpreter of expression language geevalueerd (eval(), OGNL, SpEL, EL, Jinja-expressies buiten templates). | H40: Directe code-uitvoering op de server; volledige compromittering. | I40: Injecteer rekenkundige en taalspecifieke expressies in verdachte parameters en controleer of ze worden geevalueerd (WSTG-INPV-11). | J40: Vermijd dynamische evaluatie van invoer; gebruik veilige parsers; sandbox en least privilege. | K40: Monitor op onverwachte child-processen en op expressie-syntax in requests. | L40: A05:2025 | N40: WSTG-INPV-11 | O40: V1 | P40: T1190, T1059 | Q40: CWE-94, CWE-917 | R40: Methodology and Resources | S40: Web attacks | T40: D8 | AB40: AV-WEB-16, CVE-2022-26134, CVE-2017-5638 | AD40: https://owasp.org/www-community/attacks/Code_Injection | AE40: 2026-10-09
...

Sheet Legenda
A1: Attack-vectors knowledge base - Legenda (versie 0.10.0, 2026-10-09)
A3: Kolom | B3: Betekenis | C3: Waarden / conventie
A4: ID | B4: Unieke sleutel van de rij. | C4: AV-<SCOPE>-<nn> voor attack vectors (WEB, API, NET, EXT, AD, CLD, MOB, WIFI, SE, PHY, HOST, AI); CVE-jjjj-nnnnn voor bekende kwetsbaarheden.
A5: Scope | B5: Testscope waarin de vector/kwetsbaarheid typisch wordt aangetroffen. | C5: Web application | API | Internal network | External network | Active Directory | Cloud | Mobile | Wireless | Social engineering | Physical | Endpoint | AI / LLM
A6: Vector | B6: Korte Engelse naam van de aanvalstechniek of kwetsbaarheid (rapporttitel). | C6: Vrije tekst; CVE-rijen: "<Product> - <type> (<bijnaam>)".
A7: Category | B7: Klasse van de bevinding. | C7: Bv. Authorization, Injection, Configuration, Credential access, Known vulnerability (alle CVE-rijen).
A8: Kill_chain_phase | B8: Fase (MITRE ATT&CK-tactiek) waarin de techniek doorgaans wordt ingezet. | C8: Reconnaissance | Initial access | Execution | Persistence | Privilege escalation | Defense evasion | Credential access | Discovery | Lateral movement | Collection | Command and control | Impact
A9: Severity_default | B9: Indicatieve standaardernst voor rapportage; pas aan op context en bewijs. | C9: Info | Low | Medium | High | Critical. Voor CVE-rijen gebaseerd op praktische pentest-impact; de formele CVSS-score staat in CVSS_score.
A10: Description / Impact / Test_approach / Remediation / Detection_note | B10: Rapporttekst (NL, zonder diacritics conform bestaande conventie). | C10: Test_approach beschrijft een niet-destructieve aanpak binnen de rules of engagement (RoE).
A11: OWASP_Top10_2025 | B11: Mapping op OWASP Top 10 2025. | C11: A01 Broken Access Control, A02 Security Misconfiguration, A03 Software Supply Chain Failures, A04 Cryptographic Failures, A05 Injection, A06 Insecure Design, A07 Authentication Failures, A08 Software or Data Integrity Failures, A09 Security Logging & Alerting Failures, A10 Mishandling of Exceptional Conditions. CVE-rijen krijgen A03:2025 (kwetsbare component) plus de onderliggende klasse.
A12: OWASP_API_2023 | B12: Mapping op OWASP API Security Top 10 2023. | C12: API1 t/m API10.
A13: WSTG | B13: OWASP Web Security Testing Guide test-ID (v4.2 / latest). | C13: Bv. WSTG-ATHZ-04 (IDOR), WSTG-INPV-05 (SQLi), WSTG-SESS-10 (JWT), WSTG-APIT-01 (GraphQL). Categorie-prefix blijft filterbaar.
A14: ASVS_5.0 | B14: Hoofdstuk van OWASP ASVS 5.0. | C14: V1 Encoding/Sanitization, V2 Validation/Business Logic, V3 Web Frontend, V4 API/Web Service, V5 File Handling, V6 Authentication, V7 Session, V8 Authorization, V9 Self-contained Tokens, V10 OAuth/OIDC, V11 Cryptography, V12 Secure Communication, V13 Configuration, V14 Data Protection, V15 Secure Coding/Architecture, V16 Logging/Error Handling, V17 WebRTC.
... A28: Last_updated | B28: Datum laatste review/wijziging van de rij. | C28: ISO-datum (jjjj-mm-dd).
A30: Bronnen en peildata
A31: CVE-records: CVEProject/cvelistV5 (CNA-beschrijvingen, CVSS, CISA-ADP incl. KEV-datum), stand 2026-10-04.
A32: CISA Known Exploited Vulnerabilities Catalog (via ADP-container in de CVE-records), stand 2026-10-04.
A33: OWASP Top 10 2025, OWASP API Security Top 10 2023, OWASP WSTG v4.2/latest, OWASP ASVS 5.0, OWASP Mobile Top 10 2024 / MASVS 2.x, OWASP Top 10 for LLM Applications 2025.
A34: MITRE ATT&CK Enterprise (v17/v18) en MITRE ATLAS.
A35: Leveranciersadviezen (MSRC, Fortinet PSIRT, Citrix/NetScaler, Ivanti, Palo Alto Networks, Cisco PSIRT, Broadcom/VMware, Atlassian, Oracle CPU, SAP, Adobe, GitLab, JetBrains, JFrog e.a.).
A36: Severity_default, Test_approach, Remediation en Detection_note zijn redactionele keuzes voor rapportage; CVSS/KEV/versies zijn uit de bronnen overgenomen.

Sheet Changelog
A1: Versie | B1: Datum | C1: Onderdeel | D1: Wijziging
A2: 0.10.0 | B2: 2026-10-09 | C2: Structuur | D2: 10 kolommen toegevoegd achter Evidence: CVSS_score, CVSS_vector, Affected_versions, Fixed_in, CISA_KEV, Exploit_public, Related_IDs, Other_mapping, References, Last_updated. Bestaande 21 kolommen, volgorde en kopnamen ongewijzigd.
A3: 0.10.0 | B3: 2026-10-09 | C3: Structuur | D3: Kopregel vet met vulling, bevroren eerste rij/kolom (ID), autofilter over de hele tabel; tabbladen Legenda, Changelog en Overzicht toegevoegd.
A4: 0.10.0 | B4: 2026-10-09 | C4: Attack vectors | D4: 108 nieuwe AV-rijen (totaal 195): Web +29, API +2, Internal network +14, External network (nieuw) +7, Active Directory +14, Cloud +11, Mobile +4, Wireless +4, Social engineering +5, Physical +4, Endpoint (nieuw) +7, AI / LLM (nieuw) +7.
A5: 0.10.0 | B5: 2026-10-09 | C5: Attack vectors | D5: Nieuwe scopes: External network (AV-EXT), Endpoint (AV-HOST) en AI / LLM (AV-AI) met mapping op OWASP LLM Top 10 2025 en MITRE ATLAS.
A6: 0.10.0 | B6: 2026-10-09 | C6: Bestaande rijen | D6: WSTG-kolom verfijnd van categorie (bv. WSTG-ATHZ) naar specifieke test-ID's (bv. WSTG-ATHZ-04); reflected/stored XSS verplaatst van WSTG-CLNT naar WSTG-INPV-01/02 conform WSTG.
A7: 0.10.0 | B7: 2026-10-09 | C7: Bestaande rijen | D7: MITRE ATT&CK aangevuld waar een verdedigbare mapping bestaat (o.a. SQLi/SSRF/XXE/SSTI -> T1190, file upload -> T1505.003, sessie -> T1539, JWT -> T1606, TLS -> T1557/T1040); AV-AD-08 (ACL abuse) gecorrigeerd naar T1098, T1484.001.
A8: 0.10.0 | B8: 2026-10-09 | C8: Bestaande rijen | D8: AV-AD-09 uitgebreid van ESC1-ESC8 naar ESC1-ESC16 (incl. ESC9/10 certificate mapping, ESC15 EKUwu, ESC16) met Certipy-verwijzing; AV-NET-02 uitgebreid met ADIDNS-wildcard-misbruik; AV-WEB-11 hernoemd naar "Path traversal / LFI / RFI"; AV-AD-01 remediation aangevuld met RC4-uitschakeling; AV-CLD-03 uitgebreid met snapshots/SAS-tokens; AV-WEB-18 CWE-1188 toegevoegd.
A9: 0.10.0 | B9: 2026-10-09 | C9: Bestaande rijen | D9: Related_IDs en Other_mapping (MASVS / OWASP Mobile Top 10 2024, CIS, Certipy) ingevuld; OWASP_API_2023 aangevuld voor AV-WEB-01/02/12 (IDOR, privesc, auth).
A10: 0.10.0 | B10: 2026-10-09 | C10: CVE-rijen | D10: 154 CVE-rijen (was 1). Rij CVE-2020-14008 vertaald naar NL, aangevuld (CVSS 7.2, build 14730, KEV-status, WSTG/CWE/MITRE) en categorie-typo "Known Vulnerabillity" gecorrigeerd naar "Known vulnerability".
A11: 0.10.0 | B11: 2026-10-09 | C11: CVE-rijen | D11: Selectiecriteria: in het wild misbruikt (CISA KEV) en/of structureel aangetroffen in pentests van NL-organisaties; per scope: Active Directory (11), Internal network (25), External network (47), Web application (38), Endpoint (10), Social engineering (5), Cloud (7), AI / LLM (11). 137 van de 154 CVE-rijen staan in de CISA KEV-catalogus. Dekking t/m KEV-toevoegingen van 2026-10-04 (o.a. CVE-2026-104286 FortiMail, CVE-2026-88771 NetScaler, CVE-2026-63030 WordPress, CVE-2026-33824 Windows IKEEXT).
A12: 0.10.0 | B12: 2026-10-09 | C12: CVE-rijen | D12: CVSS-score/-vector, KEV-datum en referenties automatisch overgenomen uit de officiele CVE-records (cvelistV5, CNA en CISA-ADP); temporal-metrics uit vectoren verwijderd. Uitzonderingen gedocumenteerd in Other_mapping (CVE-2020-1472 NVD 10.0 i.p.v. CNA 5.5; CVE-2020-14008 NVD 7.2; CVE-2013-4786 alleen CVSSv2).
... A14: 0.10.0 | B14: 2026-10-09 | C14: Aandachtspunten | D14: Controleer bij rapportage de actuele NVD-score en het leveranciersadvies; versienummers zijn samengevat. Severity_default is indicatief. Rijen met Last_updated 2026-10-09 zijn allemaal gereviewd in deze release.
A15: 0.9.1 | C15: Basis | D15: Oorspronkelijke knowledge base: 87 attack vectors (9 scopes) en 1 CVE-rij.

Sheet Overzicht
A1: Overzicht aantallen per scope en Severity_default (formules op tabblad attack-vectors-knowledge-base)
A3: Scope | B3: Info | C3: Low | D3: Medium | E3: High | F3: Critical | G3: Totaal | H3: waarvan CVE-rijen | I3: waarvan in KEV
A4: Web application | B4: =COUNTIFS('attack-vectors-knowledge-base'!$B:$B,$A4,'attack-vectors-knowledge-base'!$F:$F,B$3) -> 0 | C4: =COUNTIFS('attack-vectors-knowledge-base'!$B:$B,$A4,'attack-vectors-knowledge-base'!$F:$F,C$3) -> 8 | D4: =COUNTIFS('attack-vectors-knowledge-base'!$B:$B,$A4,'attack-vectors-knowledge-base'!$F:$F,D$3) -> 24 | E4: =COUNTIFS('attack-vectors-knowledge-base'!$B:$B,$A4,'attack-vectors-knowledge-base'!$F:$F,E$3) -> 22 | F4: =COUNTIFS('attack-vectors-knowledge-base'!$B:$B,$A4,'attack-vectors-knowledge-base'!$F:$F,F$3) -> 37 | G4: =SUM(B4:F4) -> 91 | H4: =COUNTIFS('attack-vectors-knowledge-base'!$B:$B,$A4,'attack-vectors-knowledge-base'!$D:$D,"Known vulnerability") -> 38 | I4: =COUNTIFS('attack-vectors-knowledge-base'!$B:$B,$A4,'attack-vectors-knowledge-base'!$Z:$Z,"Ja*") -> 36
A5: API | B5: =COUNTIFS('attack-vectors-knowledge-base'!$B:$B,$A5,'attack-vectors-knowledge-base'!$F:$F,B$3) -> 0 | C5: =COUNTIFS('attack-vectors-knowledge-base'!$B:$B,$A5,'attack-vectors-knowledge-base'!$F:$F,C$3) -> 0 | D5: =COUNTIFS('attack-vectors-knowledge-base'!$B:$B,$A5,'attack-vectors-knowledge-base'!$F:$F,D$3) -> 7 | E5: =COUNTIFS('attack-vectors-knowledge-base'!$B:$B,$A5,'attack-vectors-knowledge-base'!$F:$F,E$3) -> 5 | F5: =COUNTIFS('attack-vectors-knowledge-base'!$B:$B,$A5,'attack-vectors-knowledge-base'!$F:$F,F$3) -> 0 | G5: =SUM(B5:F5) -> 12 | H5: =COUNTIFS('attack-vectors-knowledge-base'!$B:$B,$A5,'attack-vectors-knowledge-base'!$D:$D,"Known vulnerability") -> 0 | I5: =COUNTIFS('attack-vectors-knowledge-base'!$B:$B,$A5,'attack-vectors-knowledge-base'!$Z:$Z,"Ja*") -> 0
A6: Internal network | B6: =COUNTIFS('attack-vectors-knowledge-base'!$B:$B,$A6,'attack-vectors-knowledge-base'!$F:$F,B$3) -> 1 | C6: =COUNTIFS('attack-vectors-knowledge-base'!$B:$B,$A6,'attack-vectors-knowledge-base'!$F:$F,C$3) -> 0 | D6: =COUNTIFS('attack-vectors-knowledge-base'!$B:$B,$A6,'attack-vectors-knowledge-base'!$F:$F,D$3) -> 9 | E6: =COUNTIFS('attack-vectors-knowledge-base'!$B:$B,$A6,'attack-vectors-knowledge-base'!$F:$F,E$3) -> 20 | F6: =COUNTIFS('attack-vectors-knowledge-base'!$B:$B,$A6,'attack-vectors-knowledge-base'!$F:$F,F$3) -> 18 | G6: =SUM(B6:F6) -> 48 | H6: =COUNTIFS('attack-vectors-knowledge-base'!$B:$B,$A6,'attack-vectors-knowledge-base'!$D:$D,"Known vulnerability") -> 25 | I6: =COUNTIFS('attack-vectors-knowledge-base'!$B:$B,$A6,'attack-vectors-knowledge-base'!$Z:$Z,"Ja*") -> 22
A7: External network | B7: =COUNTIFS('attack-vectors-knowledge-base'!$B:$B,$A7,'attack-vectors-knowledge-base'!$F:$F,B$3) -> 1 | C7: =COUNTIFS('attack-vectors-knowledge-base'!$B:$B,$A7,'attack-vectors-knowledge-base'!$F:$F,C$3) -> 1 | D7: =COUNTIFS('attack-vectors-knowledge-base'!$B:$B,$A7,'attack-vectors-knowledge-base'!$F:$F,D$3) -> 2 | E7: =COUNTIFS('attack-vectors-knowledge-base'!$B:$B,$A7,'attack-vectors-knowledge-base'!$F:$F,E$3) -> 6 | F7: =COUNTIFS('attack-vectors-knowledge-base'!$B:$B,$A7,'attack-vectors-knowledge-base'!$F:$F,F$3) -> 44 | G7: =SUM(B7:F7) -> 54 | H7: =COUNTIFS('attack-vectors-knowledge-base'!$B:$B,$A7,'attack-vectors-knowledge-base'!$D:$D,"Known vulnerability") -> 47 | I7: =COUNTIFS('attack-vectors-knowledge-base'!$B:$B,$A7,'attack-vectors-knowledge-base'!$Z:$Z,"Ja*") -> 47
A8: Active Directory | B8: =COUNTIFS('attack-vectors-knowledge-base'!$B:$B,$A8,'attack-vectors-knowledge-base'!$F:$F,B$3) -> 1 | C8: =COUNTIFS('attack-vectors-knowledge-base'!$B:$B,$A8,'attack-vectors-knowledge-base'!$F:$F,C$3) -> 0 | D8: =COUNTIFS('attack-vectors-knowledge-base'!$B:$B,$A8,'attack-vectors-knowledge-base'!$F:$F,D$3) -> 6 | E8: =COUNTIFS('attack-vectors-knowledge-base'!$B:$B,$A8,'attack-vectors-knowledge-base'!$F:$F,E$3) -> 27 | F8: =COUNTIFS('attack-vectors-knowledge-base'!$B:$B,$A8,'attack-vectors-knowledge-base'!$F:$F,F$3) -> 4 | G8: =SUM(B8:F8) -> 38 | H8: =COUNTIFS('attack-vectors-knowledge-base'!$B:$B,$A8,'attack-vectors-knowledge-base'!$D:$D,"Known vulnerability") -> 11 | I8: =COUNTIFS('attack-vectors-knowledge-base'!$B:$B,$A8,'attack-vectors-knowledge-base'!$Z:$Z,"Ja*") -> 8
A9: Cloud | B9: =COUNTIFS('attack-vectors-knowledge-base'!$B:$B,$A9,'attack-vectors-knowledge-base'!$F:$F,B$3) -> 1 | C9: =COUNTIFS('attack-vectors-knowledge-base'!$B:$B,$A9,'attack-vectors-knowledge-base'!$F:$F,C$3) -> 0 | D9: =COUNTIFS('attack-vectors-knowledge-base'!$B:$B,$A9,'attack-vectors-knowledge-base'!$F:$F,D$3) -> 3 | E9: =COUNTIFS('attack-vectors-knowledge-base'!$B:$B,$A9,'attack-vectors-knowledge-base'!$F:$F,E$3) -> 18 | F9: =COUNTIFS('attack-vectors-knowledge-base'!$B:$B,$A9,'attack-vectors-knowledge-base'!$F:$F,F$3) -> 4 | G9: =SUM(B9:F9) -> 26 | H9: =COUNTIFS('attack-vectors-knowledge-base'!$B:$B,$A9,'attack-vectors-knowledge-base'!$D:$D,"Known vulnerability") -> 7 | I9: =COUNTIFS('attack-vectors-knowledge-base'!$B:$B,$A9,'attack-vectors-knowledge-base'!$Z:$Z,"Ja*") -> 3
A10: Mobile | B10: =COUNTIFS('attack-vectors-knowledge-base'!$B:$B,$A10,'attack-vectors-knowledge-base'!$F:$F,B$3) -> 0 | C10: =COUNTIFS('attack-vectors-knowledge-base'!$B:$B,$A10,'attack-vectors-knowledge-base'!$F:$F,C$3) -> 1 | D10: =COUNTIFS('attack-vectors-knowledge-base'!$B:$B,$A10,'attack-vectors-knowledge-base'!$F:$F,D$3) -> 8 | E10: =COUNTIFS('attack-vectors-knowledge-base'!$B:$B,$A10,'attack-vectors-knowledge-base'!$F:$F,E$3) -> 2 | F10: =COUNTIFS('attack-vectors-knowledge-base'!$B:$B,$A10,'attack-vectors-knowledge-base'!$F:$F,F$3) -> 0 | G10: =SUM(B10:F10) -> 11 | H10: =COUNTIFS('attack-vectors-knowledge-base'!$B:$B,$A10,'attack-vectors-knowledge-base'!$D:$D,"Known vulnerability") -> 0 | I10: =COUNTIFS('attack-vectors-knowledge-base'!$B:$B,$A10,'attack-vectors-knowledge-base'!$Z:$Z,"Ja*") -> 0
A11: Wireless | B11: =COUNTIFS('attack-vectors-knowledge-base'!$B:$B,$A11,'attack-vectors-knowledge-base'!$F:$F,B$3) -> 0 | C11: =COUNTIFS('attack-vectors-knowledge-base'!$B:$B,$A11,'attack-vectors-knowledge-base'!$F:$F,C$3) -> 1 | D11: =COUNTIFS('attack-vectors-knowledge-base'!$B:$B,$A11,'attack-vectors-knowledge-base'!$F:$F,D$3) -> 2 | E11: =COUNTIFS('attack-vectors-knowledge-base'!$B:$B,$A11,'attack-vectors-knowledge-base'!$F:$F,E$3) -> 6 | F11: =COUNTIFS('attack-vectors-knowledge-base'!$B:$B,$A11,'attack-vectors-knowledge-base'!$F:$F,F$3) -> 0 | G11: =SUM(B11:F11) -> 9 | H11: =COUNTIFS('attack-vectors-knowledge-base'!$B:$B,$A11,'attack-vectors-knowledge-base'!$D:$D,"Known vulnerability") -> 0 | I11: =COUNTIFS('attack-vectors-knowledge-base'!$B:$B,$A11,'attack-vectors-knowledge-base'!$Z:$Z,"Ja*") -> 0
A12: Social engineering | B12: =COUNTIFS('attack-vectors-knowledge-base'!$B:$B,$A12,'attack-vectors-knowledge-base'!$F:$F,B$3) -> 0 | C12: =COUNTIFS('attack-vectors-knowledge-base'!$B:$B,$A12,'attack-vectors-knowledge-base'!$F:$F,C$3) -> 0 | D12: =COUNTIFS('attack-vectors-knowledge-base'!$B:$B,$A12,'attack-vectors-knowledge-base'!$F:$F,D$3) -> 4 | E12: =COUNTIFS('attack-vectors-knowledge-base'!$B:$B,$A12,'attack-vectors-knowledge-base'!$F:$F,E$3) -> 11 | F12: =COUNTIFS('attack-vectors-knowledge-base'!$B:$B,$A12,'attack-vectors-knowledge-base'!$F:$F,F$3) -> 1 | G12: =SUM(B12:F12) -> 16 | H12: =COUNTIFS('attack-vectors-knowledge-base'!$B:$B,$A12,'attack-vectors-knowledge-base'!$D:$D,"Known vulnerability") -> 5 | I12: =COUNTIFS('attack-vectors-knowledge-base'!$B:$B,$A12,'attack-vectors-knowledge-base'!$Z:$Z,"Ja*") -> 5
A13: Physical | B13: =COUNTIFS('attack-vectors-knowledge-base'!$B:$B,$A13,'attack-vectors-knowledge-base'!$F:$F,B$3) -> 0 | C13: =COUNTIFS('attack-vectors-knowledge-base'!$B:$B,$A13,'attack-vectors-knowledge-base'!$F:$F,C$3) -> 1 | D13: =COUNTIFS('attack-vectors-knowledge-base'!$B:$B,$A13,'attack-vectors-knowledge-base'!$F:$F,D$3) -> 7 | E13: =COUNTIFS('attack-vectors-knowledge-base'!$B:$B,$A13,'attack-vectors-knowledge-base'!$F:$F,E$3) -> 1 | F13: =COUNTIFS('attack-vectors-knowledge-base'!$B:$B,$A13,'attack-vectors-knowledge-base'!$F:$F,F$3) -> 0 | G13: =SUM(B13:F13) -> 9 | H13: =COUNTIFS('attack-vectors-knowledge-base'!$B:$B,$A13,'attack-vectors-knowledge-base'!$D:$D,"Known vulnerability") -> 0 | I13: =COUNTIFS('attack-vectors-knowledge-base'!$B:$B,$A13,'attack-vectors-knowledge-base'!$Z:$Z,"Ja*") -> 0
A14: Endpoint | B14: =COUNTIFS('attack-vectors-knowledge-base'!$B:$B,$A14,'attack-vectors-knowledge-base'!$F:$F,B$3) -> 0 | C14: =COUNTIFS('attack-vectors-knowledge-base'!$B:$B,$A14,'attack-vectors-knowledge-base'!$F:$F,C$3) -> 0 | D14: =COUNTIFS('attack-vectors-knowledge-base'!$B:$B,$A14,'attack-vectors-knowledge-base'!$F:$F,D$3) -> 0 | E14: =COUNTIFS('attack-vectors-knowledge-base'!$B:$B,$A14,'attack-vectors-knowledge-base'!$F:$F,E$3) -> 16 | F14: =COUNTIFS('attack-vectors-knowledge-base'!$B:$B,$A14,'attack-vectors-knowledge-base'!$F:$F,F$3) -> 1 | G14: =SUM(B14:F14) -> 17 | H14: =COUNTIFS('attack-vectors-knowledge-base'!$B:$B,$A14,'attack-vectors-knowledge-base'!$D:$D,"Known vulnerability") -> 10 | I14: =COUNTIFS('attack-vectors-knowledge-base'!$B:$B,$A14,'attack-vectors-knowledge-base'!$Z:$Z,"Ja*") -> 10
A15: AI / LLM | B15: =COUNTIFS('attack-vectors-knowledge-base'!$B:$B,$A15,'attack-vectors-knowledge-base'!$F:$F,B$3) -> 0 | C15: =COUNTIFS('attack-vectors-knowledge-base'!$B:$B,$A15,'attack-vectors-knowledge-base'!$F:$F,C$3) -> 0 | D15: =COUNTIFS('attack-vectors-knowledge-base'!$B:$B,$A15,'attack-vectors-knowledge-base'!$F:$F,D$3) -> 3 | E15: =COUNTIFS('attack-vectors-knowledge-base'!$B:$B,$A15,'attack-vectors-knowledge-base'!$F:$F,E$3) -> 6 | F15: =COUNTIFS('attack-vectors-knowledge-base'!$B:$B,$A15,'attack-vectors-knowledge-base'!$F:$F,F$3) -> 9 | G15: =SUM(B15:F15) -> 18 | H15: =COUNTIFS('attack-vectors-knowledge-base'!$B:$B,$A15,'attack-vectors-knowledge-base'!$D:$D,"Known vulnerability") -> 11 | I15: =COUNTIFS('attack-vectors-knowledge-base'!$B:$B,$A15,'attack-vectors-knowledge-base'!$Z:$Z,"Ja*") -> 6
A16: Totaal | B16: =SUM(B4:B15) -> 4 | C16: =SUM(C4:C15) -> 12 | D16: =SUM(D4:D15) -> 75 | E16: =SUM(E4:E15) -> 140 | F16: =SUM(F4:F15) -> 118 | G16: =SUM(G4:G15) -> 349 | H16: =SUM(H4:H15) -> 154 | I16: =SUM(I4:I15) -> 137
A18: Controle: aantal rijen met ID in hoofdtabel | B18: =COUNTA('attack-vectors-knowledge-base'!$A:$A)-1 -> 349
A19: Controle: aantal CVE-rijen (ID begint met CVE-) | B19: =SUMPRODUCT(--(LEFT('attack-vectors-knowledge-base'!$A$2:$A$2000,4)="CVE-")) -> 154
A20: Controle: aantal rijen in KEV | B20: =SUMPRODUCT(--(LEFT('attack-vectors-knowledge-base'!$Z$2:$Z$2000,2)="Ja")) -> 137
